Workbook
Name parms: Data!$L$2:$S$48

Sheet Overview
P1: Week | Q1: tv.fifi | R1: vod.fifi | S1: display.fifi | T1: influencer.fifi | U1: social.display.fifi | V1: social.video.fifi | W1: content.fifi | X1: generic | Y1: tv.cofi | Z1: display.cofi | AA1: social.video.cofi | AB1: vod.cofi | AC1: dooh.cofi | AD1: tv.refi | AE1: social.video.refi | AF1: vod.refi | AG1: search.umb | AH1: social.display.umb | AI1: social.video.umb | AJ1: display.umb | AK1: vod.umb | AL1: tv.umb | AM1: SUM | AN1: Ref | AP1: Scenario | AQ1: Net revenue | AS1: Media | AT1: Unconstrained | AU1: Current allocation | AW1: Product | AX1: Unconstrained | AY1: Current allocation
P2: Week_01 | Q2: =SUMIFS(Opt_uncon!$Q:$Q,Opt_uncon!$A:$A,$P2,Opt_uncon!$C:$C,Q$1) -> 71471.962 | R2: =SUMIFS(Opt_uncon!$Q:$Q,Opt_uncon!$A:$A,$P2,Opt_uncon!$C:$C,R$1) -> 11239.791 | S2: =SUMIFS(Opt_uncon!$Q:$Q,Opt_uncon!$A:$A,$P2,Opt_uncon!$C:$C,S$1) -> 0 | T2: =SUMIFS(Opt_uncon!$Q:$Q,Opt_uncon!$A:$A,$P2,Opt_uncon!$C:$C,T$1) -> 0 | U2: =SUMIFS(Opt_uncon!$Q:$Q,Opt_uncon!$A:$A,$P2,Opt_uncon!$C:$C,U$1) -> 0 | V2: =SUMIFS(Opt_uncon!$Q:$Q,Opt_uncon!$A:$A,$P2,Opt_uncon!$C:$C,V$1) -> 0 | W2: =SUMIFS(Opt_uncon!$Q:$Q,Opt_uncon!$A:$A,$P2,Opt_uncon!$C:$C,W$1) -> 0 | X2: =SUMIFS(Opt_uncon!$Q:$Q,Opt_uncon!$A:$A,$P2,Opt_uncon!$C:$C,X$1) -> 0 | ... AL2: =SUMIFS(Opt_uncon!$Q:$Q,Opt_uncon!$A:$A,$P2,Opt_uncon!$C:$C,AL$1) -> 0 | AM2: =SUM(Q2:AL2) -> 179764.87 | AN2: =SUMIFS(Opt_current!Q:Q,Opt_current!A:A,P2) -> 912.39 | AP2: Unconstrained | AQ2: =Opt_uncon!S2871 -> 17970119 | AS2: tv.fifi | AT2: =Opt_uncon!Q2847 -> 1384729.2 | AU2: =Opt_current!Q2847 -> 726517.95 | AW2: FiFi | AX2: =Opt_uncon!Q2842 -> 1803328.1 | AY2: =Opt_current!Q2842 -> 1391400.1
P3: Week_02 | Q3: =SUMIFS(Opt_uncon!$Q:$Q,Opt_uncon!$A:$A,$P3,Opt_uncon!$C:$C,Q$1) -> 69864.76 | R3: =SUMIFS(Opt_uncon!$Q:$Q,Opt_uncon!$A:$A,$P3,Opt_uncon!$C:$C,R$1) -> 9482.1055 | S3: =SUMIFS(Opt_uncon!$Q:$Q,Opt_uncon!$A:$A,$P3,Opt_uncon!$C:$C,S$1) -> 0 | T3: =SUMIFS(Opt_uncon!$Q:$Q,Opt_uncon!$A:$A,$P3,Opt_uncon!$C:$C,T$1) -> 0 | U3: =SUMIFS(Opt_uncon!$Q:$Q,Opt_uncon!$A:$A,$P3,Opt_uncon!$C:$C,U$1) -> 44.358017 | V3: =SUMIFS(Opt_uncon!$Q:$Q,Opt_uncon!$A:$A,$P3,Opt_uncon!$C:$C,V$1) -> 0 | W3: =SUMIFS(Opt_uncon!$Q:$Q,Opt_uncon!$A:$A,$P3,Opt_uncon!$C:$C,W$1) -> 0 | X3: =SUMIFS(Opt_uncon!$Q:$Q,Opt_uncon!$A:$A,$P3,Opt_uncon!$C:$C,X$1) -> 0 | ... AL3: =SUMIFS(Opt_uncon!$Q:$Q,Opt_uncon!$A:$A,$P3,Opt_uncon!$C:$C,AL$1) -> 0 | AM3: =SUM(Q3:AL3) -> 260483.38 | AN3: =SUMIFS(Opt_current!Q:Q,Opt_current!A:A,P3) -> 167262.8 | AP3: Partially constrained | AQ3: =Opt_partial!S2871 -> 17684061 | AS3: vod.fifi | AT3: =Opt_uncon!Q2848 -> 406285.69 | AU3: =Opt_current!Q2848 -> 484480.75 | AW3: CoFi | AX3: =Opt_uncon!Q2843 -> 696298.72 | AY3: =Opt_current!Q2843 -> 1175354.6
P4: Week_03 | Q4: =SUMIFS(Opt_uncon!$Q:$Q,Opt_uncon!$A:$A,$P4,Opt_uncon!$C:$C,Q$1) -> 11944.44 | R4: =SUMIFS(Opt_uncon!$Q:$Q,Opt_uncon!$A:$A,$P4,Opt_uncon!$C:$C,R$1) -> 8215.5392 | S4: =SUMIFS(Opt_uncon!$Q:$Q,Opt_uncon!$A:$A,$P4,Opt_uncon!$C:$C,S$1) -> 0 | T4: =SUMIFS(Opt_uncon!$Q:$Q,Opt_uncon!$A:$A,$P4,Opt_uncon!$C:$C,T$1) -> 0 | U4: =SUMIFS(Opt_uncon!$Q:$Q,Opt_uncon!$A:$A,$P4,Opt_uncon!$C:$C,U$1) -> 0 | V4: =SUMIFS(Opt_uncon!$Q:$Q,Opt_uncon!$A:$A,$P4,Opt_uncon!$C:$C,V$1) -> 0 | W4: =SUMIFS(Opt_uncon!$Q:$Q,Opt_uncon!$A:$A,$P4,Opt_uncon!$C:$C,W$1) -> 0 | X4: =SUMIFS(Opt_uncon!$Q:$Q,Opt_uncon!$A:$A,$P4,Opt_uncon!$C:$C,X$1) -> 0 | ... AL4: =SUMIFS(Opt_uncon!$Q:$Q,Opt_uncon!$A:$A,$P4,Opt_uncon!$C:$C,AL$1) -> 0 | AM4: =SUM(Q4:AL4) -> 52041.946 | AN4: =SUMIFS(Opt_current!Q:Q,Opt_current!A:A,P4) -> 145659.7 | AP4: Current allocation | AQ4: =Opt_current!S2871 -> 11136074 | AS4: display.fifi | AT4: =Opt_uncon!Q2849 -> 0 | AU4: =Opt_current!Q2849 -> 60893.968 | AW4: ReFi | AX4: =Opt_uncon!Q2844 -> 1285466.7 | AY4: =Opt_current!Q2844 -> 1259749.3
P5: Week_04 | Q5: =SUMIFS(Opt_uncon!$Q:$Q,Opt_uncon!$A:$A,$P5,Opt_uncon!$C:$C,Q$1) -> 31953.064 | R5: =SUMIFS(Opt_uncon!$Q:$Q,Opt_uncon!$A:$A,$P5,Opt_uncon!$C:$C,R$1) -> 6785.4142 | S5: =SUMIFS(Opt_uncon!$Q:$Q,Opt_uncon!$A:$A,$P5,Opt_uncon!$C:$C,S$1) -> 0 | T5: =SUMIFS(Opt_uncon!$Q:$Q,Opt_uncon!$A:$A,$P5,Opt_uncon!$C:$C,T$1) -> 0 | U5: =SUMIFS(Opt_uncon!$Q:$Q,Opt_uncon!$A:$A,$P5,Opt_uncon!$C:$C,U$1) -> 0 | V5: =SUMIFS(Opt_uncon!$Q:$Q,Opt_uncon!$A:$A,$P5,Opt_uncon!$C:$C,V$1) -> 0 | W5: =SUMIFS(Opt_uncon!$Q:$Q,Opt_uncon!$A:$A,$P5,Opt_uncon!$C:$C,W$1) -> 0 | X5: =SUMIFS(Opt_uncon!$Q:$Q,Opt_uncon!$A:$A,$P5,Opt_uncon!$C:$C,X$1) -> 0 | ... AL5: =SUMIFS(Opt_uncon!$Q:$Q,Opt_uncon!$A:$A,$P5,Opt_uncon!$C:$C,AL$1) -> 0 | AM5: =SUM(Q5:AL5) -> 94047.912 | AN5: =SUMIFS(Opt_current!Q:Q,Opt_current!A:A,P5) -> 141289.74 | AS5: influencer.fifi | AT5: =Opt_uncon!Q2850 -> 0 | AU5: =Opt_current!Q2850 -> 0 | AW5: Umbrella | AX5: =Opt_uncon!Q2845 -> 930493.09 | AY5: =Opt_current!Q2845 -> 889081.4
P6: Week_05 | Q6: =SUMIFS(Opt_uncon!$Q:$Q,Opt_uncon!$A:$A,$P6,Opt_uncon!$C:$C,Q$1) -> 18929.073 | R6: =SUMIFS(Opt_uncon!$Q:$Q,Opt_uncon!$A:$A,$P6,Opt_uncon!$C:$C,R$1) -> 8050.0596 | S6: =SUMIFS(Opt_uncon!$Q:$Q,Opt_uncon!$A:$A,$P6,Opt_uncon!$C:$C,S$1) -> 0 | T6: =SUMIFS(Opt_uncon!$Q:$Q,Opt_uncon!$A:$A,$P6,Opt_uncon!$C:$C,T$1) -> 0 | U6: =SUMIFS(Opt_uncon!$Q:$Q,Opt_uncon!$A:$A,$P6,Opt_uncon!$C:$C,U$1) -> 0 | V6: =SUMIFS(Opt_uncon!$Q:$Q,Opt_uncon!$A:$A,$P6,Opt_uncon!$C:$C,V$1) -> 0 | W6: =SUMIFS(Opt_uncon!$Q:$Q,Opt_uncon!$A:$A,$P6,Opt_uncon!$C:$C,W$1) -> 0 | X6: =SUMIFS(Opt_uncon!$Q:$Q,Opt_uncon!$A:$A,$P6,Opt_uncon!$C:$C,X$1) -> 0 | ... AL6: =SUMIFS(Opt_uncon!$Q:$Q,Opt_uncon!$A:$A,$P6,Opt_uncon!$C:$C,AL$1) -> 0 | AM6: =SUM(Q6:AL6) -> 98054.871 | AN6: =SUMIFS(Opt_current!Q:Q,Opt_current!A:A,P6) -> 89536.126 | AS6: social.display.fifi | AT6: =Opt_uncon!Q2851 -> 4544.4463 | AU6: =Opt_current!Q2851 -> 3000 | AX6: Unconstrained | AY6: Current allocation | AZ6: Delta
P7: Week_06 | Q7: =SUMIFS(Opt_uncon!$Q:$Q,Opt_uncon!$A:$A,$P7,Opt_uncon!$C:$C,Q$1) -> 19946.281 | R7: =SUMIFS(Opt_uncon!$Q:$Q,Opt_uncon!$A:$A,$P7,Opt_uncon!$C:$C,R$1) -> 6551.1358 | S7: =SUMIFS(Opt_uncon!$Q:$Q,Opt_uncon!$A:$A,$P7,Opt_uncon!$C:$C,S$1) -> 0 | T7: =SUMIFS(Opt_uncon!$Q:$Q,Opt_uncon!$A:$A,$P7,Opt_uncon!$C:$C,T$1) -> 0 | U7: =SUMIFS(Opt_uncon!$Q:$Q,Opt_uncon!$A:$A,$P7,Opt_uncon!$C:$C,U$1) -> 0 | V7: =SUMIFS(Opt_uncon!$Q:$Q,Opt_uncon!$A:$A,$P7,Opt_uncon!$C:$C,V$1) -> 0 | W7: =SUMIFS(Opt_uncon!$Q:$Q,Opt_uncon!$A:$A,$P7,Opt_uncon!$C:$C,W$1) -> 0 | X7: =SUMIFS(Opt_uncon!$Q:$Q,Opt_uncon!$A:$A,$P7,Opt_uncon!$C:$C,X$1) -> 0 | ... AL7: =SUMIFS(Opt_uncon!$Q:$Q,Opt_uncon!$A:$A,$P7,Opt_uncon!$C:$C,AL$1) -> 0 | AM7: =SUM(Q7:AL7) -> 107257.64 | AN7: =SUMIFS(Opt_current!Q:Q,Opt_current!A:A,P7) -> 255333.94 | AS7: social.video.fifi | AT7: =Opt_uncon!Q2852 -> 7768.77 | AU7: =Opt_current!Q2852 -> 76507.4 | AW7: =AW2 -> FiFi | AX7: =AX2/1000 -> 1803.3281 | AY7: =AY2/1000 -> 1391.4001 | AZ7: =AX7-AY7 -> 411.92803
P8: Week_07 | Q8: =SUMIFS(Opt_uncon!$Q:$Q,Opt_uncon!$A:$A,$P8,Opt_uncon!$C:$C,Q$1) -> 50408.301 | R8: =SUMIFS(Opt_uncon!$Q:$Q,Opt_uncon!$A:$A,$P8,Opt_uncon!$C:$C,R$1) -> 10434.398 | S8: =SUMIFS(Opt_uncon!$Q:$Q,Opt_uncon!$A:$A,$P8,Opt_uncon!$C:$C,S$1) -> 0 | T8: =SUMIFS(Opt_uncon!$Q:$Q,Opt_uncon!$A:$A,$P8,Opt_uncon!$C:$C,T$1) -> 0 | U8: =SUMIFS(Opt_uncon!$Q:$Q,Opt_uncon!$A:$A,$P8,Opt_uncon!$C:$C,U$1) -> 389.51735 | V8: =SUMIFS(Opt_uncon!$Q:$Q,Opt_uncon!$A:$A,$P8,Opt_uncon!$C:$C,V$1) -> 505.42586 | W8: =SUMIFS(Opt_uncon!$Q:$Q,Opt_uncon!$A:$A,$P8,Opt_uncon!$C:$C,W$1) -> 0 | X8: =SUMIFS(Opt_uncon!$Q:$Q,Opt_uncon!$A:$A,$P8,Opt_uncon!$C:$C,X$1) -> 0 | ... AL8: =SUMIFS(Opt_uncon!$Q:$Q,Opt_uncon!$A:$A,$P8,Opt_uncon!$C:$C,AL$1) -> 0 | AM8: =SUM(Q8:AL8) -> 89013.922 | AN8: =SUMIFS(Opt_current!Q:Q,Opt_current!A:A,P8) -> 29802.471 | AS8: content.fifi | AT8: =Opt_uncon!Q2853 -> 0 | AU8: =Opt_current!Q2853 -> 40000 | AW8: =AW3 -> CoFi | AX8: =AX3/1000 -> 696.29872 | AY8: =AY3/1000 -> 1175.3546 | AZ8: =AX8-AY8 -> -479.0559
P9: Week_08 | Q9: =SUMIFS(Opt_uncon!$Q:$Q,Opt_uncon!$A:$A,$P9,Opt_uncon!$C:$C,Q$1) -> 41982.615 | R9: =SUMIFS(Opt_uncon!$Q:$Q,Opt_uncon!$A:$A,$P9,Opt_uncon!$C:$C,R$1) -> 8372.6405 | S9: =SUMIFS(Opt_uncon!$Q:$Q,Opt_uncon!$A:$A,$P9,Opt_uncon!$C:$C,S$1) -> 0 | T9: =SUMIFS(Opt_uncon!$Q:$Q,Opt_uncon!$A:$A,$P9,Opt_uncon!$C:$C,T$1) -> 0 | U9: =SUMIFS(Opt_uncon!$Q:$Q,Opt_uncon!$A:$A,$P9,Opt_uncon!$C:$C,U$1) -> 0 | V9: =SUMIFS(Opt_uncon!$Q:$Q,Opt_uncon!$A:$A,$P9,Opt_uncon!$C:$C,V$1) -> 0 | W9: =SUMIFS(Opt_uncon!$Q:$Q,Opt_uncon!$A:$A,$P9,Opt_uncon!$C:$C,W$1) -> 0 | X9: =SUMIFS(Opt_uncon!$Q:$Q,Opt_uncon!$A:$A,$P9,Opt_uncon!$C:$C,X$1) -> 0 | ... AL9: =SUMIFS(Opt_uncon!$Q:$Q,Opt_uncon!$A:$A,$P9,Opt_uncon!$C:$C,AL$1) -> 0 | AM9: =SUM(Q9:AL9) -> 169713.25 | AN9: =SUMIFS(Opt_current!Q:Q,Opt_current!A:A,P9) -> 97717.923 | AS9: generic | AT9: =Opt_uncon!Q2854 -> 0 | AU9: =Opt_current!Q2854 -> 0 | AW9: =AW4 -> ReFi | AX9: =AX4/1000 -> 1285.4667 | AY9: =AY4/1000 -> 1259.7493 | AZ9: =AX9-AY9 -> 25.717406
P10: Week_09 | Q10: =SUMIFS(Opt_uncon!$Q:$Q,Opt_uncon!$A:$A,$P10,Opt_uncon!$C:$C,Q$1) -> 11280.911 | R10: =SUMIFS(Opt_uncon!$Q:$Q,Opt_uncon!$A:$A,$P10,Opt_uncon!$C:$C,R$1) -> 8454.6262 | S10: =SUMIFS(Opt_uncon!$Q:$Q,Opt_uncon!$A:$A,$P10,Opt_uncon!$C:$C,S$1) -> 0 | T10: =SUMIFS(Opt_uncon!$Q:$Q,Opt_uncon!$A:$A,$P10,Opt_uncon!$C:$C,T$1) -> 0 | U10: =SUMIFS(Opt_uncon!$Q:$Q,Opt_uncon!$A:$A,$P10,Opt_uncon!$C:$C,U$1) -> 0 | V10: =SUMIFS(Opt_uncon!$Q:$Q,Opt_uncon!$A:$A,$P10,Opt_uncon!$C:$C,V$1) -> 0 | W10: =SUMIFS(Opt_uncon!$Q:$Q,Opt_uncon!$A:$A,$P10,Opt_uncon!$C:$C,W$1) -> 0 | X10: =SUMIFS(Opt_uncon!$Q:$Q,Opt_uncon!$A:$A,$P10,Opt_uncon!$C:$C,X$1) -> 0 | ... AL10: =SUMIFS(Opt_uncon!$Q:$Q,Opt_uncon!$A:$A,$P10,Opt_uncon!$C:$C,AL$1) -> 0 | AM10: =SUM(Q10:AL10) -> 73120.066 | AN10: =SUMIFS(Opt_current!Q:Q,Opt_current!A:A,P10) -> 34902.628 | AS10: tv.cofi | AT10: =Opt_uncon!Q2855 -> 509479.86 | AU10: =Opt_current!Q2855 -> 841651.8 | AW10: =AW5 -> Umbrella | AX10: =AX5/1000 -> 930.49309 | AY10: =AY5/1000 -> 889.0814 | AZ10: =AX10-AY10 -> 41.411689
P11: Week_10 | Q11: =SUMIFS(Opt_uncon!$Q:$Q,Opt_uncon!$A:$A,$P11,Opt_uncon!$C:$C,Q$1) -> 41399.672 | R11: =SUMIFS(Opt_uncon!$Q:$Q,Opt_uncon!$A:$A,$P11,Opt_uncon!$C:$C,R$1) -> 7977.2094 | S11: =SUMIFS(Opt_uncon!$Q:$Q,Opt_uncon!$A:$A,$P11,Opt_uncon!$C:$C,S$1) -> 0 | T11: =SUMIFS(Opt_uncon!$Q:$Q,Opt_uncon!$A:$A,$P11,Opt_uncon!$C:$C,T$1) -> 0 | U11: =SUMIFS(Opt_uncon!$Q:$Q,Opt_uncon!$A:$A,$P11,Opt_uncon!$C:$C,U$1) -> 0 | V11: =SUMIFS(Opt_uncon!$Q:$Q,Opt_uncon!$A:$A,$P11,Opt_uncon!$C:$C,V$1) -> 0 | W11: =SUMIFS(Opt_uncon!$Q:$Q,Opt_uncon!$A:$A,$P11,Opt_uncon!$C:$C,W$1) -> 0 | X11: =SUMIFS(Opt_uncon!$Q:$Q,Opt_uncon!$A:$A,$P11,Opt_uncon!$C:$C,X$1) -> 0 | ... AL11: =SUMIFS(Opt_uncon!$Q:$Q,Opt_uncon!$A:$A,$P11,Opt_uncon!$C:$C,AL$1) -> 0 | AM11: =SUM(Q11:AL11) -> 162281.05 | AN11: =SUMIFS(Opt_current!Q:Q,Opt_current!A:A,P11) -> 135926.37 | AS11: display.cofi | AT11: =Opt_uncon!Q2856 -> 0 | AU11: =Opt_current!Q2856 -> 0
P12: Week_11 | Q12: =SUMIFS(Opt_uncon!$Q:$Q,Opt_uncon!$A:$A,$P12,Opt_uncon!$C:$C,Q$1) -> 25899.868 | R12: =SUMIFS(Opt_uncon!$Q:$Q,Opt_uncon!$A:$A,$P12,Opt_uncon!$C:$C,R$1) -> 9848.6633 | S12: =SUMIFS(Opt_uncon!$Q:$Q,Opt_uncon!$A:$A,$P12,Opt_uncon!$C:$C,S$1) -> 0 | T12: =SUMIFS(Opt_uncon!$Q:$Q,Opt_uncon!$A:$A,$P12,Opt_uncon!$C:$C,T$1) -> 0 | U12: =SUMIFS(Opt_uncon!$Q:$Q,Opt_uncon!$A:$A,$P12,Opt_uncon!$C:$C,U$1) -> 288.88408 | V12: =SUMIFS(Opt_uncon!$Q:$Q,Opt_uncon!$A:$A,$P12,Opt_uncon!$C:$C,V$1) -> 301.21277 | W12: =SUMIFS(Opt_uncon!$Q:$Q,Opt_uncon!$A:$A,$P12,Opt_uncon!$C:$C,W$1) -> 0 | X12: =SUMIFS(Opt_uncon!$Q:$Q,Opt_uncon!$A:$A,$P12,Opt_uncon!$C:$C,X$1) -> 0 | ... AL12: =SUMIFS(Opt_uncon!$Q:$Q,Opt_uncon!$A:$A,$P12,Opt_uncon!$C:$C,AL$1) -> 0 | AM12: =SUM(Q12:AL12) -> 72573.106 | AN12: =SUMIFS(Opt_current!Q:Q,Opt_current!A:A,P12) -> 54013.252 | AS12: social.video.cofi | AT12: =Opt_uncon!Q2857 -> 0 | AU12: =Opt_current!Q2857 -> 78902.23
P13: Week_12 | Q13: =SUMIFS(Opt_uncon!$Q:$Q,Opt_uncon!$A:$A,$P13,Opt_uncon!$C:$C,Q$1) -> 34287.041 | R13: =SUMIFS(Opt_uncon!$Q:$Q,Opt_uncon!$A:$A,$P13,Opt_uncon!$C:$C,R$1) -> 8319.6843 | S13: =SUMIFS(Opt_uncon!$Q:$Q,Opt_uncon!$A:$A,$P13,Opt_uncon!$C:$C,S$1) -> 0 | T13: =SUMIFS(Opt_uncon!$Q:$Q,Opt_uncon!$A:$A,$P13,Opt_uncon!$C:$C,T$1) -> 0 | U13: =SUMIFS(Opt_uncon!$Q:$Q,Opt_uncon!$A:$A,$P13,Opt_uncon!$C:$C,U$1) -> 0 | V13: =SUMIFS(Opt_uncon!$Q:$Q,Opt_uncon!$A:$A,$P13,Opt_uncon!$C:$C,V$1) -> 0 | W13: =SUMIFS(Opt_uncon!$Q:$Q,Opt_uncon!$A:$A,$P13,Opt_uncon!$C:$C,W$1) -> 0 | X13: =SUMIFS(Opt_uncon!$Q:$Q,Opt_uncon!$A:$A,$P13,Opt_uncon!$C:$C,X$1) -> 0 | ... AL13: =SUMIFS(Opt_uncon!$Q:$Q,Opt_uncon!$A:$A,$P13,Opt_uncon!$C:$C,AL$1) -> 0 | AM13: =SUM(Q13:AL13) -> 92817.489 | AN13: =SUMIFS(Opt_current!Q:Q,Opt_current!A:A,P13) -> 197114.96 | AS13: vod.cofi | AT13: =Opt_uncon!Q2858 -> 186818.87 | AU13: =Opt_current!Q2858 -> 254800.59
P14: Week_13 | Q14: =SUMIFS(Opt_uncon!$Q:$Q,Opt_uncon!$A:$A,$P14,Opt_uncon!$C:$C,Q$1) -> 31544.049 | R14: =SUMIFS(Opt_uncon!$Q:$Q,Opt_uncon!$A:$A,$P14,Opt_uncon!$C:$C,R$1) -> 10993.417 | S14: =SUMIFS(Opt_uncon!$Q:$Q,Opt_uncon!$A:$A,$P14,Opt_uncon!$C:$C,S$1) -> 0 | T14: =SUMIFS(Opt_uncon!$Q:$Q,Opt_uncon!$A:$A,$P14,Opt_uncon!$C:$C,T$1) -> 0 | U14: =SUMIFS(Opt_uncon!$Q:$Q,Opt_uncon!$A:$A,$P14,Opt_uncon!$C:$C,U$1) -> 1641.4053 | V14: =SUMIFS(Opt_uncon!$Q:$Q,Opt_uncon!$A:$A,$P14,Opt_uncon!$C:$C,V$1) -> 3053.9854 | W14: =SUMIFS(Opt_uncon!$Q:$Q,Opt_uncon!$A:$A,$P14,Opt_uncon!$C:$C,W$1) -> 0 | X14: =SUMIFS(Opt_uncon!$Q:$Q,Opt_uncon!$A:$A,$P14,Opt_uncon!$C:$C,X$1) -> 0 | ... AL14: =SUMIFS(Opt_uncon!$Q:$Q,Opt_uncon!$A:$A,$P14,Opt_uncon!$C:$C,AL$1) -> 0 | AM14: =SUM(Q14:AL14) -> 90382.92 | AN14: =SUMIFS(Opt_current!Q:Q,Opt_current!A:A,P14) -> 52141.314 | AS14: dooh.cofi | AT14: =Opt_uncon!Q2859 -> 0 | AU14: =Opt_current!Q2859 -> 0
P15: Week_14 | Q15: =SUMIFS(Opt_uncon!$Q:$Q,Opt_uncon!$A:$A,$P15,Opt_uncon!$C:$C,Q$1) -> 64544.939 | R15: =SUMIFS(Opt_uncon!$Q:$Q,Opt_uncon!$A:$A,$P15,Opt_uncon!$C:$C,R$1) -> 9238.4945 | S15: =SUMIFS(Opt_uncon!$Q:$Q,Opt_uncon!$A:$A,$P15,Opt_uncon!$C:$C,S$1) -> 0 | T15: =SUMIFS(Opt_uncon!$Q:$Q,Opt_uncon!$A:$A,$P15,Opt_uncon!$C:$C,T$1) -> 0 | U15: =SUMIFS(Opt_uncon!$Q:$Q,Opt_uncon!$A:$A,$P15,Opt_uncon!$C:$C,U$1) -> 351.19442 | V15: =SUMIFS(Opt_uncon!$Q:$Q,Opt_uncon!$A:$A,$P15,Opt_uncon!$C:$C,V$1) -> 470.43146 | W15: =SUMIFS(Opt_uncon!$Q:$Q,Opt_uncon!$A:$A,$P15,Opt_uncon!$C:$C,W$1) -> 0 | X15: =SUMIFS(Opt_uncon!$Q:$Q,Opt_uncon!$A:$A,$P15,Opt_uncon!$C:$C,X$1) -> 0 | ... AL15: =SUMIFS(Opt_uncon!$Q:$Q,Opt_uncon!$A:$A,$P15,Opt_uncon!$C:$C,AL$1) -> 0 | AM15: =SUM(Q15:AL15) -> 229203.15 | AN15: =SUMIFS(Opt_current!Q:Q,Opt_current!A:A,P15) -> 188501.12 | AS15: tv.refi | AT15: =Opt_uncon!Q2860 -> 959745.67 | AU15: =Opt_current!Q2860 -> 831671.46
P16: Week_15 | Q16: =SUMIFS(Opt_uncon!$Q:$Q,Opt_uncon!$A:$A,$P16,Opt_uncon!$C:$C,Q$1) -> 0 | R16: =SUMIFS(Opt_uncon!$Q:$Q,Opt_uncon!$A:$A,$P16,Opt_uncon!$C:$C,R$1) -> 5322.8804 | S16: =SUMIFS(Opt_uncon!$Q:$Q,Opt_uncon!$A:$A,$P16,Opt_uncon!$C:$C,S$1) -> 0 | T16: =SUMIFS(Opt_uncon!$Q:$Q,Opt_uncon!$A:$A,$P16,Opt_uncon!$C:$C,T$1) -> 0 | U16: =SUMIFS(Opt_uncon!$Q:$Q,Opt_uncon!$A:$A,$P16,Opt_uncon!$C:$C,U$1) -> 0 | V16: =SUMIFS(Opt_uncon!$Q:$Q,Opt_uncon!$A:$A,$P16,Opt_uncon!$C:$C,V$1) -> 0 | W16: =SUMIFS(Opt_uncon!$Q:$Q,Opt_uncon!$A:$A,$P16,Opt_uncon!$C:$C,W$1) -> 0 | X16: =SUMIFS(Opt_uncon!$Q:$Q,Opt_uncon!$A:$A,$P16,Opt_uncon!$C:$C,X$1) -> 0 | ... AL16: =SUMIFS(Opt_uncon!$Q:$Q,Opt_uncon!$A:$A,$P16,Opt_uncon!$C:$C,AL$1) -> 0 | AM16: =SUM(Q16:AL16) -> 27341.824 | AN16: =SUMIFS(Opt_current!Q:Q,Opt_current!A:A,P16) -> 59690.684 | AS16: social.video.refi | AT16: =Opt_uncon!Q2861 -> 0 | AU16: =Opt_current!Q2861 -> 98130.83
P17: Week_16 | Q17: =SUMIFS(Opt_uncon!$Q:$Q,Opt_uncon!$A:$A,$P17,Opt_uncon!$C:$C,Q$1) -> 34179.029 | R17: =SUMIFS(Opt_uncon!$Q:$Q,Opt_uncon!$A:$A,$P17,Opt_uncon!$C:$C,R$1) -> 9643.9661 | S17: =SUMIFS(Opt_uncon!$Q:$Q,Opt_uncon!$A:$A,$P17,Opt_uncon!$C:$C,S$1) -> 0 | T17: =SUMIFS(Opt_uncon!$Q:$Q,Opt_uncon!$A:$A,$P17,Opt_uncon!$C:$C,T$1) -> 0 | U17: =SUMIFS(Opt_uncon!$Q:$Q,Opt_uncon!$A:$A,$P17,Opt_uncon!$C:$C,U$1) -> 0 | V17: =SUMIFS(Opt_uncon!$Q:$Q,Opt_uncon!$A:$A,$P17,Opt_uncon!$C:$C,V$1) -> 0 | W17: =SUMIFS(Opt_uncon!$Q:$Q,Opt_uncon!$A:$A,$P17,Opt_uncon!$C:$C,W$1) -> 0 | X17: =SUMIFS(Opt_uncon!$Q:$Q,Opt_uncon!$A:$A,$P17,Opt_uncon!$C:$C,X$1) -> 0 | ... AL17: =SUMIFS(Opt_uncon!$Q:$Q,Opt_uncon!$A:$A,$P17,Opt_uncon!$C:$C,AL$1) -> 0 | AM17: =SUM(Q17:AL17) -> 129721.59 | AN17: =SUMIFS(Opt_current!Q:Q,Opt_current!A:A,P17) -> 227116 | AS17: vod.refi | AT17: =Opt_uncon!Q2862 -> 325721.06 | AU17: =Opt_current!Q2862 -> 329947.03
P18: Week_17 | Q18: =SUMIFS(Opt_uncon!$Q:$Q,Opt_uncon!$A:$A,$P18,Opt_uncon!$C:$C,Q$1) -> 3500 | R18: =SUMIFS(Opt_uncon!$Q:$Q,Opt_uncon!$A:$A,$P18,Opt_uncon!$C:$C,R$1) -> 7424.7557 | S18: =SUMIFS(Opt_uncon!$Q:$Q,Opt_uncon!$A:$A,$P18,Opt_uncon!$C:$C,S$1) -> 0 | T18: =SUMIFS(Opt_uncon!$Q:$Q,Opt_uncon!$A:$A,$P18,Opt_uncon!$C:$C,T$1) -> 0 | U18: =SUMIFS(Opt_uncon!$Q:$Q,Opt_uncon!$A:$A,$P18,Opt_uncon!$C:$C,U$1) -> 0 | V18: =SUMIFS(Opt_uncon!$Q:$Q,Opt_uncon!$A:$A,$P18,Opt_uncon!$C:$C,V$1) -> 0 | W18: =SUMIFS(Opt_uncon!$Q:$Q,Opt_uncon!$A:$A,$P18,Opt_uncon!$C:$C,W$1) -> 0 | X18: =SUMIFS(Opt_uncon!$Q:$Q,Opt_uncon!$A:$A,$P18,Opt_uncon!$C:$C,X$1) -> 0 | ... AL18: =SUMIFS(Opt_uncon!$Q:$Q,Opt_uncon!$A:$A,$P18,Opt_uncon!$C:$C,AL$1) -> 0 | AM18: =SUM(Q18:AL18) -> 64528.197 | AN18: =SUMIFS(Opt_current!Q:Q,Opt_current!A:A,P18) -> 36888.911 | AS18: search.umb | AT18: =Opt_uncon!Q2863 -> 189878.85 | AU18: =Opt_current!Q2863 -> 83646.43
P19: Week_18 | Q19: =SUMIFS(Opt_uncon!$Q:$Q,Opt_uncon!$A:$A,$P19,Opt_uncon!$C:$C,Q$1) -> 0 | R19: =SUMIFS(Opt_uncon!$Q:$Q,Opt_uncon!$A:$A,$P19,Opt_uncon!$C:$C,R$1) -> 6044.1381 | S19: =SUMIFS(Opt_uncon!$Q:$Q,Opt_uncon!$A:$A,$P19,Opt_uncon!$C:$C,S$1) -> 0 | T19: =SUMIFS(Opt_uncon!$Q:$Q,Opt_uncon!$A:$A,$P19,Opt_uncon!$C:$C,T$1) -> 0 | U19: =SUMIFS(Opt_uncon!$Q:$Q,Opt_uncon!$A:$A,$P19,Opt_uncon!$C:$C,U$1) -> 0 | V19: =SUMIFS(Opt_uncon!$Q:$Q,Opt_uncon!$A:$A,$P19,Opt_uncon!$C:$C,V$1) -> 0 | W19: =SUMIFS(Opt_uncon!$Q:$Q,Opt_uncon!$A:$A,$P19,Opt_uncon!$C:$C,W$1) -> 0 | X19: =SUMIFS(Opt_uncon!$Q:$Q,Opt_uncon!$A:$A,$P19,Opt_uncon!$C:$C,X$1) -> 0 | ... AL19: =SUMIFS(Opt_uncon!$Q:$Q,Opt_uncon!$A:$A,$P19,Opt_uncon!$C:$C,AL$1) -> 0 | AM19: =SUM(Q19:AL19) -> 22952.619 | AN19: =SUMIFS(Opt_current!Q:Q,Opt_current!A:A,P19) -> 37445.561 | AS19: social.display.umb | AT19: =Opt_uncon!Q2864 -> 41390.3 | AU19: =Opt_current!Q2864 -> 186825
P20: Week_19 | Q20: =SUMIFS(Opt_uncon!$Q:$Q,Opt_uncon!$A:$A,$P20,Opt_uncon!$C:$C,Q$1) -> 84746.469 | R20: =SUMIFS(Opt_uncon!$Q:$Q,Opt_uncon!$A:$A,$P20,Opt_uncon!$C:$C,R$1) -> 11811.35 | S20: =SUMIFS(Opt_uncon!$Q:$Q,Opt_uncon!$A:$A,$P20,Opt_uncon!$C:$C,S$1) -> 0 | T20: =SUMIFS(Opt_uncon!$Q:$Q,Opt_uncon!$A:$A,$P20,Opt_uncon!$C:$C,T$1) -> 0 | U20: =SUMIFS(Opt_uncon!$Q:$Q,Opt_uncon!$A:$A,$P20,Opt_uncon!$C:$C,U$1) -> 1829.0872 | V20: =SUMIFS(Opt_uncon!$Q:$Q,Opt_uncon!$A:$A,$P20,Opt_uncon!$C:$C,V$1) -> 3437.7145 | W20: =SUMIFS(Opt_uncon!$Q:$Q,Opt_uncon!$A:$A,$P20,Opt_uncon!$C:$C,W$1) -> 0 | X20: =SUMIFS(Opt_uncon!$Q:$Q,Opt_uncon!$A:$A,$P20,Opt_uncon!$C:$C,X$1) -> 0 | ... AL20: =SUMIFS(Opt_uncon!$Q:$Q,Opt_uncon!$A:$A,$P20,Opt_uncon!$C:$C,AL$1) -> 0 | AM20: =SUM(Q20:AL20) -> 138370.72 | AN20: =SUMIFS(Opt_current!Q:Q,Opt_current!A:A,P20) -> 55699.179 | AS20: social.video.umb | AT20: =Opt_uncon!Q2865 -> 114100.7 | AU20: =Opt_current!Q2865 -> 468232.08
P21: Week_20 | Q21: =SUMIFS(Opt_uncon!$Q:$Q,Opt_uncon!$A:$A,$P21,Opt_uncon!$C:$C,Q$1) -> 0 | R21: =SUMIFS(Opt_uncon!$Q:$Q,Opt_uncon!$A:$A,$P21,Opt_uncon!$C:$C,R$1) -> 7095.2704 | S21: =SUMIFS(Opt_uncon!$Q:$Q,Opt_uncon!$A:$A,$P21,Opt_uncon!$C:$C,S$1) -> 0 | T21: =SUMIFS(Opt_uncon!$Q:$Q,Opt_uncon!$A:$A,$P21,Opt_uncon!$C:$C,T$1) -> 0 | U21: =SUMIFS(Opt_uncon!$Q:$Q,Opt_uncon!$A:$A,$P21,Opt_uncon!$C:$C,U$1) -> 0 | V21: =SUMIFS(Opt_uncon!$Q:$Q,Opt_uncon!$A:$A,$P21,Opt_uncon!$C:$C,V$1) -> 0 | W21: =SUMIFS(Opt_uncon!$Q:$Q,Opt_uncon!$A:$A,$P21,Opt_uncon!$C:$C,W$1) -> 0 | X21: =SUMIFS(Opt_uncon!$Q:$Q,Opt_uncon!$A:$A,$P21,Opt_uncon!$C:$C,X$1) -> 0 | ... AL21: =SUMIFS(Opt_uncon!$Q:$Q,Opt_uncon!$A:$A,$P21,Opt_uncon!$C:$C,AL$1) -> 0 | AM21: =SUM(Q21:AL21) -> 38180.756 | AN21: =SUMIFS(Opt_current!Q:Q,Opt_current!A:A,P21) -> 54602.966 | AS21: display.umb | AT21: =Opt_uncon!Q2866 -> 0 | AU21: =Opt_current!Q2866 -> 150377.89
P22: Week_21 | Q22: =SUMIFS(Opt_uncon!$Q:$Q,Opt_uncon!$A:$A,$P22,Opt_uncon!$C:$C,Q$1) -> 0 | R22: =SUMIFS(Opt_uncon!$Q:$Q,Opt_uncon!$A:$A,$P22,Opt_uncon!$C:$C,R$1) -> 5960.0198 | S22: =SUMIFS(Opt_uncon!$Q:$Q,Opt_uncon!$A:$A,$P22,Opt_uncon!$C:$C,S$1) -> 0 | T22: =SUMIFS(Opt_uncon!$Q:$Q,Opt_uncon!$A:$A,$P22,Opt_uncon!$C:$C,T$1) -> 0 | U22: =SUMIFS(Opt_uncon!$Q:$Q,Opt_uncon!$A:$A,$P22,Opt_uncon!$C:$C,U$1) -> 0 | V22: =SUMIFS(Opt_uncon!$Q:$Q,Opt_uncon!$A:$A,$P22,Opt_uncon!$C:$C,V$1) -> 0 | W22: =SUMIFS(Opt_uncon!$Q:$Q,Opt_uncon!$A:$A,$P22,Opt_uncon!$C:$C,W$1) -> 0 | X22: =SUMIFS(Opt_uncon!$Q:$Q,Opt_uncon!$A:$A,$P22,Opt_uncon!$C:$C,X$1) -> 0 | ... AL22: =SUMIFS(Opt_uncon!$Q:$Q,Opt_uncon!$A:$A,$P22,Opt_uncon!$C:$C,AL$1) -> 0 | AM22: =SUM(Q22:AL22) -> 117286.86 | AN22: =SUMIFS(Opt_current!Q:Q,Opt_current!A:A,P22) -> 61166.497 | AS22: vod.umb | AT22: =Opt_uncon!Q2867 -> 585123.24 | AU22: =Opt_current!Q2867 -> 0
P23: Week_22 | Q23: =SUMIFS(Opt_uncon!$Q:$Q,Opt_uncon!$A:$A,$P23,Opt_uncon!$C:$C,Q$1) -> 5074.1514 | R23: =SUMIFS(Opt_uncon!$Q:$Q,Opt_uncon!$A:$A,$P23,Opt_uncon!$C:$C,R$1) -> 5999.7797 | S23: =SUMIFS(Opt_uncon!$Q:$Q,Opt_uncon!$A:$A,$P23,Opt_uncon!$C:$C,S$1) -> 0 | T23: =SUMIFS(Opt_uncon!$Q:$Q,Opt_uncon!$A:$A,$P23,Opt_uncon!$C:$C,T$1) -> 0 | U23: =SUMIFS(Opt_uncon!$Q:$Q,Opt_uncon!$A:$A,$P23,Opt_uncon!$C:$C,U$1) -> 0 | V23: =SUMIFS(Opt_uncon!$Q:$Q,Opt_uncon!$A:$A,$P23,Opt_uncon!$C:$C,V$1) -> 0 | W23: =SUMIFS(Opt_uncon!$Q:$Q,Opt_uncon!$A:$A,$P23,Opt_uncon!$C:$C,W$1) -> 0 | X23: =SUMIFS(Opt_uncon!$Q:$Q,Opt_uncon!$A:$A,$P23,Opt_uncon!$C:$C,X$1) -> 0 | ... AL23: =SUMIFS(Opt_uncon!$Q:$Q,Opt_uncon!$A:$A,$P23,Opt_uncon!$C:$C,AL$1) -> 0 | AM23: =SUM(Q23:AL23) -> 33962.035 | AN23: =SUMIFS(Opt_current!Q:Q,Opt_current!A:A,P23) -> 49848.302 | AS23: tv.umb | AT23: =Opt_uncon!#REF! -> #REF! | AU23: =Opt_current!#REF! -> #REF!
P24: Week_23 | Q24: =SUMIFS(Opt_uncon!$Q:$Q,Opt_uncon!$A:$A,$P24,Opt_uncon!$C:$C,Q$1) -> 37148.669 | R24: =SUMIFS(Opt_uncon!$Q:$Q,Opt_uncon!$A:$A,$P24,Opt_uncon!$C:$C,R$1) -> 5409.2153 | S24: =SUMIFS(Opt_uncon!$Q:$Q,Opt_uncon!$A:$A,$P24,Opt_uncon!$C:$C,S$1) -> 0 | T24: =SUMIFS(Opt_uncon!$Q:$Q,Opt_uncon!$A:$A,$P24,Opt_uncon!$C:$C,T$1) -> 0 | U24: =SUMIFS(Opt_uncon!$Q:$Q,Opt_uncon!$A:$A,$P24,Opt_uncon!$C:$C,U$1) -> 0 | V24: =SUMIFS(Opt_uncon!$Q:$Q,Opt_uncon!$A:$A,$P24,Opt_uncon!$C:$C,V$1) -> 0 | W24: =SUMIFS(Opt_uncon!$Q:$Q,Opt_uncon!$A:$A,$P24,Opt_uncon!$C:$C,W$1) -> 0 | X24: =SUMIFS(Opt_uncon!$Q:$Q,Opt_uncon!$A:$A,$P24,Opt_uncon!$C:$C,X$1) -> 0 | ... AL24: =SUMIFS(Opt_uncon!$Q:$Q,Opt_uncon!$A:$A,$P24,Opt_uncon!$C:$C,AL$1) -> 0 | AM24: =SUM(Q24:AL24) -> 76795.035 | AN24: =SUMIFS(Opt_current!Q:Q,Opt_current!A:A,P24) -> 45377.804
P25: Week_24 | Q25: =SUMIFS(Opt_uncon!$Q:$Q,Opt_uncon!$A:$A,$P25,Opt_uncon!$C:$C,Q$1) -> 58242.28 | R25: =SUMIFS(Opt_uncon!$Q:$Q,Opt_uncon!$A:$A,$P25,Opt_uncon!$C:$C,R$1) -> 9908.0584 | S25: =SUMIFS(Opt_uncon!$Q:$Q,Opt_uncon!$A:$A,$P25,Opt_uncon!$C:$C,S$1) -> 0 | T25: =SUMIFS(Opt_uncon!$Q:$Q,Opt_uncon!$A:$A,$P25,Opt_uncon!$C:$C,T$1) -> 0 | U25: =SUMIFS(Opt_uncon!$Q:$Q,Opt_uncon!$A:$A,$P25,Opt_uncon!$C:$C,U$1) -> 0 | V25: =SUMIFS(Opt_uncon!$Q:$Q,Opt_uncon!$A:$A,$P25,Opt_uncon!$C:$C,V$1) -> 0 | W25: =SUMIFS(Opt_uncon!$Q:$Q,Opt_uncon!$A:$A,$P25,Opt_uncon!$C:$C,W$1) -> 0 | X25: =SUMIFS(Opt_uncon!$Q:$Q,Opt_uncon!$A:$A,$P25,Opt_uncon!$C:$C,X$1) -> 0 | ... AL25: =SUMIFS(Opt_uncon!$Q:$Q,Opt_uncon!$A:$A,$P25,Opt_uncon!$C:$C,AL$1) -> 0 | AM25: =SUM(Q25:AL25) -> 123710.17 | AN25: =SUMIFS(Opt_current!Q:Q,Opt_current!A:A,P25) -> 19672.879
P26: Week_25 | Q26: =SUMIFS(Opt_uncon!$Q:$Q,Opt_uncon!$A:$A,$P26,Opt_uncon!$C:$C,Q$1) -> 3500 | R26: =SUMIFS(Opt_uncon!$Q:$Q,Opt_uncon!$A:$A,$P26,Opt_uncon!$C:$C,R$1) -> 5200.9031 | S26: =SUMIFS(Opt_uncon!$Q:$Q,Opt_uncon!$A:$A,$P26,Opt_uncon!$C:$C,S$1) -> 0 | T26: =SUMIFS(Opt_uncon!$Q:$Q,Opt_uncon!$A:$A,$P26,Opt_uncon!$C:$C,T$1) -> 0 | U26: =SUMIFS(Opt_uncon!$Q:$Q,Opt_uncon!$A:$A,$P26,Opt_uncon!$C:$C,U$1) -> 0 | V26: =SUMIFS(Opt_uncon!$Q:$Q,Opt_uncon!$A:$A,$P26,Opt_uncon!$C:$C,V$1) -> 0 | W26: =SUMIFS(Opt_uncon!$Q:$Q,Opt_uncon!$A:$A,$P26,Opt_uncon!$C:$C,W$1) -> 0 | X26: =SUMIFS(Opt_uncon!$Q:$Q,Opt_uncon!$A:$A,$P26,Opt_uncon!$C:$C,X$1) -> 0 | ... AL26: =SUMIFS(Opt_uncon!$Q:$Q,Opt_uncon!$A:$A,$P26,Opt_uncon!$C:$C,AL$1) -> 0 | AM26: =SUM(Q26:AL26) -> 49064.364 | AN26: =SUMIFS(Opt_current!Q:Q,Opt_current!A:A,P26) -> 22904.523 | AS26: Total
P27: Week_26 | Q27: =SUMIFS(Opt_uncon!$Q:$Q,Opt_uncon!$A:$A,$P27,Opt_uncon!$C:$C,Q$1) -> 15365.798 | R27: =SUMIFS(Opt_uncon!$Q:$Q,Opt_uncon!$A:$A,$P27,Opt_uncon!$C:$C,R$1) -> 5509.3168 | S27: =SUMIFS(Opt_uncon!$Q:$Q,Opt_uncon!$A:$A,$P27,Opt_uncon!$C:$C,S$1) -> 0 | T27: =SUMIFS(Opt_uncon!$Q:$Q,Opt_uncon!$A:$A,$P27,Opt_uncon!$C:$C,T$1) -> 0 | U27: =SUMIFS(Opt_uncon!$Q:$Q,Opt_uncon!$A:$A,$P27,Opt_uncon!$C:$C,U$1) -> 0 | V27: =SUMIFS(Opt_uncon!$Q:$Q,Opt_uncon!$A:$A,$P27,Opt_uncon!$C:$C,V$1) -> 0 | W27: =SUMIFS(Opt_uncon!$Q:$Q,Opt_uncon!$A:$A,$P27,Opt_uncon!$C:$C,W$1) -> 0 | X27: =SUMIFS(Opt_uncon!$Q:$Q,Opt_uncon!$A:$A,$P27,Opt_uncon!$C:$C,X$1) -> 0 | ... AL27: =SUMIFS(Opt_uncon!$Q:$Q,Opt_uncon!$A:$A,$P27,Opt_uncon!$C:$C,AL$1) -> 0 | AM27: =SUM(Q27:AL27) -> 101852.77 | AN27: =SUMIFS(Opt_current!Q:Q,Opt_current!A:A,P27) -> 12328.234 | AT27: Unconstrained | AU27: As-is | AV27: Delta
P28: Week_27 | Q28: =SUMIFS(Opt_uncon!$Q:$Q,Opt_uncon!$A:$A,$P28,Opt_uncon!$C:$C,Q$1) -> 41968.871 | R28: =SUMIFS(Opt_uncon!$Q:$Q,Opt_uncon!$A:$A,$P28,Opt_uncon!$C:$C,R$1) -> 8174.6663 | S28: =SUMIFS(Opt_uncon!$Q:$Q,Opt_uncon!$A:$A,$P28,Opt_uncon!$C:$C,S$1) -> 0 | T28: =SUMIFS(Opt_uncon!$Q:$Q,Opt_uncon!$A:$A,$P28,Opt_uncon!$C:$C,T$1) -> 0 | U28: =SUMIFS(Opt_uncon!$Q:$Q,Opt_uncon!$A:$A,$P28,Opt_uncon!$C:$C,U$1) -> 0 | V28: =SUMIFS(Opt_uncon!$Q:$Q,Opt_uncon!$A:$A,$P28,Opt_uncon!$C:$C,V$1) -> 0 | W28: =SUMIFS(Opt_uncon!$Q:$Q,Opt_uncon!$A:$A,$P28,Opt_uncon!$C:$C,W$1) -> 0 | X28: =SUMIFS(Opt_uncon!$Q:$Q,Opt_uncon!$A:$A,$P28,Opt_uncon!$C:$C,X$1) -> 0 | ... AL28: =SUMIFS(Opt_uncon!$Q:$Q,Opt_uncon!$A:$A,$P28,Opt_uncon!$C:$C,AL$1) -> 0 | AM28: =SUM(Q28:AL28) -> 107148.21 | AN28: =SUMIFS(Opt_current!Q:Q,Opt_current!A:A,P28) -> 7543.54 | AS28: TV | AT28: =SUM(AT2,AT10,AT15)/1000 -> 2853.9547 | AU28: =SUM(AU2,AU10,AU15)/1000 -> 2399.8412 | AV28: =AT28-AU28 -> 454.11351
P29: Week_28 | Q29: =SUMIFS(Opt_uncon!$Q:$Q,Opt_uncon!$A:$A,$P29,Opt_uncon!$C:$C,Q$1) -> 42674.656 | R29: =SUMIFS(Opt_uncon!$Q:$Q,Opt_uncon!$A:$A,$P29,Opt_uncon!$C:$C,R$1) -> 8506.7959 | S29: =SUMIFS(Opt_uncon!$Q:$Q,Opt_uncon!$A:$A,$P29,Opt_uncon!$C:$C,S$1) -> 0 | T29: =SUMIFS(Opt_uncon!$Q:$Q,Opt_uncon!$A:$A,$P29,Opt_uncon!$C:$C,T$1) -> 0 | U29: =SUMIFS(Opt_uncon!$Q:$Q,Opt_uncon!$A:$A,$P29,Opt_uncon!$C:$C,U$1) -> 0 | V29: =SUMIFS(Opt_uncon!$Q:$Q,Opt_uncon!$A:$A,$P29,Opt_uncon!$C:$C,V$1) -> 0 | W29: =SUMIFS(Opt_uncon!$Q:$Q,Opt_uncon!$A:$A,$P29,Opt_uncon!$C:$C,W$1) -> 0 | X29: =SUMIFS(Opt_uncon!$Q:$Q,Opt_uncon!$A:$A,$P29,Opt_uncon!$C:$C,X$1) -> 0 | ... AL29: =SUMIFS(Opt_uncon!$Q:$Q,Opt_uncon!$A:$A,$P29,Opt_uncon!$C:$C,AL$1) -> 0 | AM29: =SUM(Q29:AL29) -> 126899.76 | AN29: =SUMIFS(Opt_current!Q:Q,Opt_current!A:A,P29) -> 16700.232 | AS29: VOD | AT29: =SUM(AT3,AT13,AT17,AT22)/1000 -> 1503.9489 | AU29: =SUM(AU3,AU13,AU17,AU22)/1000 -> 1069.2284 | AV29: =AT29-AU29 -> 434.72048
P30: Week_29 | Q30: =SUMIFS(Opt_uncon!$Q:$Q,Opt_uncon!$A:$A,$P30,Opt_uncon!$C:$C,Q$1) -> 6403.4655 | R30: =SUMIFS(Opt_uncon!$Q:$Q,Opt_uncon!$A:$A,$P30,Opt_uncon!$C:$C,R$1) -> 5283.812 | S30: =SUMIFS(Opt_uncon!$Q:$Q,Opt_uncon!$A:$A,$P30,Opt_uncon!$C:$C,S$1) -> 0 | T30: =SUMIFS(Opt_uncon!$Q:$Q,Opt_uncon!$A:$A,$P30,Opt_uncon!$C:$C,T$1) -> 0 | U30: =SUMIFS(Opt_uncon!$Q:$Q,Opt_uncon!$A:$A,$P30,Opt_uncon!$C:$C,U$1) -> 0 | V30: =SUMIFS(Opt_uncon!$Q:$Q,Opt_uncon!$A:$A,$P30,Opt_uncon!$C:$C,V$1) -> 0 | W30: =SUMIFS(Opt_uncon!$Q:$Q,Opt_uncon!$A:$A,$P30,Opt_uncon!$C:$C,W$1) -> 0 | X30: =SUMIFS(Opt_uncon!$Q:$Q,Opt_uncon!$A:$A,$P30,Opt_uncon!$C:$C,X$1) -> 0 | ... AL30: =SUMIFS(Opt_uncon!$Q:$Q,Opt_uncon!$A:$A,$P30,Opt_uncon!$C:$C,AL$1) -> 0 | AM30: =SUM(Q30:AL30) -> 54519.56 | AN30: =SUMIFS(Opt_current!Q:Q,Opt_current!A:A,P30) -> 21551.548 | AS30: Display | AT30: =SUM(AT4,AT21,AT11)/1000 -> 0 | AU30: =SUM(AU4,AU21,AU11)/1000 -> 211.27186 | AV30: =AT30-AU30 -> -211.27186
P31: Week_30 | Q31: =SUMIFS(Opt_uncon!$Q:$Q,Opt_uncon!$A:$A,$P31,Opt_uncon!$C:$C,Q$1) -> 27978.295 | R31: =SUMIFS(Opt_uncon!$Q:$Q,Opt_uncon!$A:$A,$P31,Opt_uncon!$C:$C,R$1) -> 6596.3276 | S31: =SUMIFS(Opt_uncon!$Q:$Q,Opt_uncon!$A:$A,$P31,Opt_uncon!$C:$C,S$1) -> 0 | T31: =SUMIFS(Opt_uncon!$Q:$Q,Opt_uncon!$A:$A,$P31,Opt_uncon!$C:$C,T$1) -> 0 | U31: =SUMIFS(Opt_uncon!$Q:$Q,Opt_uncon!$A:$A,$P31,Opt_uncon!$C:$C,U$1) -> 0 | V31: =SUMIFS(Opt_uncon!$Q:$Q,Opt_uncon!$A:$A,$P31,Opt_uncon!$C:$C,V$1) -> 0 | W31: =SUMIFS(Opt_uncon!$Q:$Q,Opt_uncon!$A:$A,$P31,Opt_uncon!$C:$C,W$1) -> 0 | X31: =SUMIFS(Opt_uncon!$Q:$Q,Opt_uncon!$A:$A,$P31,Opt_uncon!$C:$C,X$1) -> 0 | ... AL31: =SUMIFS(Opt_uncon!$Q:$Q,Opt_uncon!$A:$A,$P31,Opt_uncon!$C:$C,AL$1) -> 0 | AM31: =SUM(Q31:AL31) -> 115811.99 | AN31: =SUMIFS(Opt_current!Q:Q,Opt_current!A:A,P31) -> 34659.953 | AS31: Social Video | AT31: =SUM(AT7,AT12,AT16+AT20)/1000 -> 121.86947 | AU31: =SUM(AU7,AU12,AU16,AU20)/1000 -> 721.77254 | AV31: =AT31-AU31 -> -599.90307
P32: Week_31 | Q32: =SUMIFS(Opt_uncon!$Q:$Q,Opt_uncon!$A:$A,$P32,Opt_uncon!$C:$C,Q$1) -> 6066.3631 | R32: =SUMIFS(Opt_uncon!$Q:$Q,Opt_uncon!$A:$A,$P32,Opt_uncon!$C:$C,R$1) -> 6976.1453 | S32: =SUMIFS(Opt_uncon!$Q:$Q,Opt_uncon!$A:$A,$P32,Opt_uncon!$C:$C,S$1) -> 0 | T32: =SUMIFS(Opt_uncon!$Q:$Q,Opt_uncon!$A:$A,$P32,Opt_uncon!$C:$C,T$1) -> 0 | U32: =SUMIFS(Opt_uncon!$Q:$Q,Opt_uncon!$A:$A,$P32,Opt_uncon!$C:$C,U$1) -> 0 | V32: =SUMIFS(Opt_uncon!$Q:$Q,Opt_uncon!$A:$A,$P32,Opt_uncon!$C:$C,V$1) -> 0 | W32: =SUMIFS(Opt_uncon!$Q:$Q,Opt_uncon!$A:$A,$P32,Opt_uncon!$C:$C,W$1) -> 0 | X32: =SUMIFS(Opt_uncon!$Q:$Q,Opt_uncon!$A:$A,$P32,Opt_uncon!$C:$C,X$1) -> 0 | ... AL32: =SUMIFS(Opt_uncon!$Q:$Q,Opt_uncon!$A:$A,$P32,Opt_uncon!$C:$C,AL$1) -> 0 | AM32: =SUM(Q32:AL32) -> 35339.247 | AN32: =SUMIFS(Opt_current!Q:Q,Opt_current!A:A,P32) -> 142300.36 | AS32: Social Display | AT32: =SUM(AT6,AT19)/1000 -> 45.934747 | AU32: =SUM(AU6,AU19)/1000 -> 189.825 | AV32: =AT32-AU32 -> -143.89025
P33: Week_32 | Q33: =SUMIFS(Opt_uncon!$Q:$Q,Opt_uncon!$A:$A,$P33,Opt_uncon!$C:$C,Q$1) -> 26219.11 | R33: =SUMIFS(Opt_uncon!$Q:$Q,Opt_uncon!$A:$A,$P33,Opt_uncon!$C:$C,R$1) -> 7377.7601 | S33: =SUMIFS(Opt_uncon!$Q:$Q,Opt_uncon!$A:$A,$P33,Opt_uncon!$C:$C,S$1) -> 0 | T33: =SUMIFS(Opt_uncon!$Q:$Q,Opt_uncon!$A:$A,$P33,Opt_uncon!$C:$C,T$1) -> 0 | U33: =SUMIFS(Opt_uncon!$Q:$Q,Opt_uncon!$A:$A,$P33,Opt_uncon!$C:$C,U$1) -> 0 | V33: =SUMIFS(Opt_uncon!$Q:$Q,Opt_uncon!$A:$A,$P33,Opt_uncon!$C:$C,V$1) -> 0 | W33: =SUMIFS(Opt_uncon!$Q:$Q,Opt_uncon!$A:$A,$P33,Opt_uncon!$C:$C,W$1) -> 0 | X33: =SUMIFS(Opt_uncon!$Q:$Q,Opt_uncon!$A:$A,$P33,Opt_uncon!$C:$C,X$1) -> 0 | ... AL33: =SUMIFS(Opt_uncon!$Q:$Q,Opt_uncon!$A:$A,$P33,Opt_uncon!$C:$C,AL$1) -> 0 | AM33: =SUM(Q33:AL33) -> 51458.834 | AN33: =SUMIFS(Opt_current!Q:Q,Opt_current!A:A,P33) -> 177191.11 | AS33: Search | AT33: =SUM(AT18)/1000 -> 189.87885 | AU33: =SUM(AU18)/1000 -> 83.64643 | AV33: =AT33-AU33 -> 106.23242
P34: Week_33 | Q34: =SUMIFS(Opt_uncon!$Q:$Q,Opt_uncon!$A:$A,$P34,Opt_uncon!$C:$C,Q$1) -> 23139.008 | R34: =SUMIFS(Opt_uncon!$Q:$Q,Opt_uncon!$A:$A,$P34,Opt_uncon!$C:$C,R$1) -> 6631.0223 | S34: =SUMIFS(Opt_uncon!$Q:$Q,Opt_uncon!$A:$A,$P34,Opt_uncon!$C:$C,S$1) -> 0 | T34: =SUMIFS(Opt_uncon!$Q:$Q,Opt_uncon!$A:$A,$P34,Opt_uncon!$C:$C,T$1) -> 0 | U34: =SUMIFS(Opt_uncon!$Q:$Q,Opt_uncon!$A:$A,$P34,Opt_uncon!$C:$C,U$1) -> 0 | V34: =SUMIFS(Opt_uncon!$Q:$Q,Opt_uncon!$A:$A,$P34,Opt_uncon!$C:$C,V$1) -> 0 | W34: =SUMIFS(Opt_uncon!$Q:$Q,Opt_uncon!$A:$A,$P34,Opt_uncon!$C:$C,W$1) -> 0 | X34: =SUMIFS(Opt_uncon!$Q:$Q,Opt_uncon!$A:$A,$P34,Opt_uncon!$C:$C,X$1) -> 0 | ... AL34: =SUMIFS(Opt_uncon!$Q:$Q,Opt_uncon!$A:$A,$P34,Opt_uncon!$C:$C,AL$1) -> 0 | AM34: =SUM(Q34:AL34) -> 101783.66 | AN34: =SUMIFS(Opt_current!Q:Q,Opt_current!A:A,P34) -> 178028.08 | AS34: Influencer | AT34: =AT5 -> 0 | AU34: =AU5 -> 0 | AV34: =AT34-AU34 -> 0
P35: Week_34 | Q35: =SUMIFS(Opt_uncon!$Q:$Q,Opt_uncon!$A:$A,$P35,Opt_uncon!$C:$C,Q$1) -> 33982.187 | R35: =SUMIFS(Opt_uncon!$Q:$Q,Opt_uncon!$A:$A,$P35,Opt_uncon!$C:$C,R$1) -> 7824.1234 | S35: =SUMIFS(Opt_uncon!$Q:$Q,Opt_uncon!$A:$A,$P35,Opt_uncon!$C:$C,S$1) -> 0 | T35: =SUMIFS(Opt_uncon!$Q:$Q,Opt_uncon!$A:$A,$P35,Opt_uncon!$C:$C,T$1) -> 0 | U35: =SUMIFS(Opt_uncon!$Q:$Q,Opt_uncon!$A:$A,$P35,Opt_uncon!$C:$C,U$1) -> 0 | V35: =SUMIFS(Opt_uncon!$Q:$Q,Opt_uncon!$A:$A,$P35,Opt_uncon!$C:$C,V$1) -> 0 | W35: =SUMIFS(Opt_uncon!$Q:$Q,Opt_uncon!$A:$A,$P35,Opt_uncon!$C:$C,W$1) -> 0 | X35: =SUMIFS(Opt_uncon!$Q:$Q,Opt_uncon!$A:$A,$P35,Opt_uncon!$C:$C,X$1) -> 0 | ... AL35: =SUMIFS(Opt_uncon!$Q:$Q,Opt_uncon!$A:$A,$P35,Opt_uncon!$C:$C,AL$1) -> 0 | AM35: =SUM(Q35:AL35) -> 88489.285 | AN35: =SUMIFS(Opt_current!Q:Q,Opt_current!A:A,P35) -> 36462.684 | AS35: Content P | AT35: =AT8/1000 -> 0 | AU35: =AU8/1000 -> 40
P36: Week_35 | Q36: =SUMIFS(Opt_uncon!$Q:$Q,Opt_uncon!$A:$A,$P36,Opt_uncon!$C:$C,Q$1) -> 0 | R36: =SUMIFS(Opt_uncon!$Q:$Q,Opt_uncon!$A:$A,$P36,Opt_uncon!$C:$C,R$1) -> 6856.437 | S36: =SUMIFS(Opt_uncon!$Q:$Q,Opt_uncon!$A:$A,$P36,Opt_uncon!$C:$C,S$1) -> 0 | T36: =SUMIFS(Opt_uncon!$Q:$Q,Opt_uncon!$A:$A,$P36,Opt_uncon!$C:$C,T$1) -> 0 | U36: =SUMIFS(Opt_uncon!$Q:$Q,Opt_uncon!$A:$A,$P36,Opt_uncon!$C:$C,U$1) -> 0 | V36: =SUMIFS(Opt_uncon!$Q:$Q,Opt_uncon!$A:$A,$P36,Opt_uncon!$C:$C,V$1) -> 0 | W36: =SUMIFS(Opt_uncon!$Q:$Q,Opt_uncon!$A:$A,$P36,Opt_uncon!$C:$C,W$1) -> 0 | X36: =SUMIFS(Opt_uncon!$Q:$Q,Opt_uncon!$A:$A,$P36,Opt_uncon!$C:$C,X$1) -> 0 | ... AL36: =SUMIFS(Opt_uncon!$Q:$Q,Opt_uncon!$A:$A,$P36,Opt_uncon!$C:$C,AL$1) -> 0 | AM36: =SUM(Q36:AL36) -> 31216.612 | AN36: =SUMIFS(Opt_current!Q:Q,Opt_current!A:A,P36) -> 249733.6
P37: Week_36 | Q37: =SUMIFS(Opt_uncon!$Q:$Q,Opt_uncon!$A:$A,$P37,Opt_uncon!$C:$C,Q$1) -> 0 | R37: =SUMIFS(Opt_uncon!$Q:$Q,Opt_uncon!$A:$A,$P37,Opt_uncon!$C:$C,R$1) -> 8197.2865 | S37: =SUMIFS(Opt_uncon!$Q:$Q,Opt_uncon!$A:$A,$P37,Opt_uncon!$C:$C,S$1) -> 0 | T37: =SUMIFS(Opt_uncon!$Q:$Q,Opt_uncon!$A:$A,$P37,Opt_uncon!$C:$C,T$1) -> 0 | U37: =SUMIFS(Opt_uncon!$Q:$Q,Opt_uncon!$A:$A,$P37,Opt_uncon!$C:$C,U$1) -> 0 | V37: =SUMIFS(Opt_uncon!$Q:$Q,Opt_uncon!$A:$A,$P37,Opt_uncon!$C:$C,V$1) -> 0 | W37: =SUMIFS(Opt_uncon!$Q:$Q,Opt_uncon!$A:$A,$P37,Opt_uncon!$C:$C,W$1) -> 0 | X37: =SUMIFS(Opt_uncon!$Q:$Q,Opt_uncon!$A:$A,$P37,Opt_uncon!$C:$C,X$1) -> 0 | ... AL37: =SUMIFS(Opt_uncon!$Q:$Q,Opt_uncon!$A:$A,$P37,Opt_uncon!$C:$C,AL$1) -> 0 | AM37: =SUM(Q37:AL37) -> 31376.776 | AN37: =SUMIFS(Opt_current!Q:Q,Opt_current!A:A,P37) -> 58136.135
P38: Week_37 | Q38: =SUMIFS(Opt_uncon!$Q:$Q,Opt_uncon!$A:$A,$P38,Opt_uncon!$C:$C,Q$1) -> 24943.739 | R38: =SUMIFS(Opt_uncon!$Q:$Q,Opt_uncon!$A:$A,$P38,Opt_uncon!$C:$C,R$1) -> 5458.3641 | S38: =SUMIFS(Opt_uncon!$Q:$Q,Opt_uncon!$A:$A,$P38,Opt_uncon!$C:$C,S$1) -> 0 | T38: =SUMIFS(Opt_uncon!$Q:$Q,Opt_uncon!$A:$A,$P38,Opt_uncon!$C:$C,T$1) -> 0 | U38: =SUMIFS(Opt_uncon!$Q:$Q,Opt_uncon!$A:$A,$P38,Opt_uncon!$C:$C,U$1) -> 0 | V38: =SUMIFS(Opt_uncon!$Q:$Q,Opt_uncon!$A:$A,$P38,Opt_uncon!$C:$C,V$1) -> 0 | W38: =SUMIFS(Opt_uncon!$Q:$Q,Opt_uncon!$A:$A,$P38,Opt_uncon!$C:$C,W$1) -> 0 | X38: =SUMIFS(Opt_uncon!$Q:$Q,Opt_uncon!$A:$A,$P38,Opt_uncon!$C:$C,X$1) -> 0 | ... AL38: =SUMIFS(Opt_uncon!$Q:$Q,Opt_uncon!$A:$A,$P38,Opt_uncon!$C:$C,AL$1) -> 0 | AM38: =SUM(Q38:AL38) -> 72916.906 | AN38: =SUMIFS(Opt_current!Q:Q,Opt_current!A:A,P38) -> 198187.15 | AT38: =SUM(AT28:AT35) -> 4715.5866 | AU38: =SUM(AU28:AU35) -> 4715.5854
P39: Week_38 | Q39: =SUMIFS(Opt_uncon!$Q:$Q,Opt_uncon!$A:$A,$P39,Opt_uncon!$C:$C,Q$1) -> 41551.758 | R39: =SUMIFS(Opt_uncon!$Q:$Q,Opt_uncon!$A:$A,$P39,Opt_uncon!$C:$C,R$1) -> 7298.0467 | S39: =SUMIFS(Opt_uncon!$Q:$Q,Opt_uncon!$A:$A,$P39,Opt_uncon!$C:$C,S$1) -> 0 | T39: =SUMIFS(Opt_uncon!$Q:$Q,Opt_uncon!$A:$A,$P39,Opt_uncon!$C:$C,T$1) -> 0 | U39: =SUMIFS(Opt_uncon!$Q:$Q,Opt_uncon!$A:$A,$P39,Opt_uncon!$C:$C,U$1) -> 0 | V39: =SUMIFS(Opt_uncon!$Q:$Q,Opt_uncon!$A:$A,$P39,Opt_uncon!$C:$C,V$1) -> 0 | W39: =SUMIFS(Opt_uncon!$Q:$Q,Opt_uncon!$A:$A,$P39,Opt_uncon!$C:$C,W$1) -> 0 | X39: =SUMIFS(Opt_uncon!$Q:$Q,Opt_uncon!$A:$A,$P39,Opt_uncon!$C:$C,X$1) -> 0 | ... AL39: =SUMIFS(Opt_uncon!$Q:$Q,Opt_uncon!$A:$A,$P39,Opt_uncon!$C:$C,AL$1) -> 0 | AM39: =SUM(Q39:AL39) -> 136624.36 | AN39: =SUMIFS(Opt_current!Q:Q,Opt_current!A:A,P39) -> 72436.2
P40: Week_39 | Q40: =SUMIFS(Opt_uncon!$Q:$Q,Opt_uncon!$A:$A,$P40,Opt_uncon!$C:$C,Q$1) -> 31522.039 | R40: =SUMIFS(Opt_uncon!$Q:$Q,Opt_uncon!$A:$A,$P40,Opt_uncon!$C:$C,R$1) -> 9409.6543 | S40: =SUMIFS(Opt_uncon!$Q:$Q,Opt_uncon!$A:$A,$P40,Opt_uncon!$C:$C,S$1) -> 0 | T40: =SUMIFS(Opt_uncon!$Q:$Q,Opt_uncon!$A:$A,$P40,Opt_uncon!$C:$C,T$1) -> 0 | U40: =SUMIFS(Opt_uncon!$Q:$Q,Opt_uncon!$A:$A,$P40,Opt_uncon!$C:$C,U$1) -> 0 | V40: =SUMIFS(Opt_uncon!$Q:$Q,Opt_uncon!$A:$A,$P40,Opt_uncon!$C:$C,V$1) -> 0 | W40: =SUMIFS(Opt_uncon!$Q:$Q,Opt_uncon!$A:$A,$P40,Opt_uncon!$C:$C,W$1) -> 0 | X40: =SUMIFS(Opt_uncon!$Q:$Q,Opt_uncon!$A:$A,$P40,Opt_uncon!$C:$C,X$1) -> 0 | ... AL40: =SUMIFS(Opt_uncon!$Q:$Q,Opt_uncon!$A:$A,$P40,Opt_uncon!$C:$C,AL$1) -> 0 | AM40: =SUM(Q40:AL40) -> 64998.567 | AN40: =SUMIFS(Opt_current!Q:Q,Opt_current!A:A,P40) -> 278885.2
...

Sheet Opt_uncon
A1: Period | B1: Product | C1: Media | D1: Halo | E1: Group | F1: VolumeBase | G1: Price | H1: UpliftMax | I1: UpliftFactor | J1: UnitSlope | K1: Carryover | L1: CostPerUnit | M1: SpendFixed | N1: SpendMin | O1: SpendMax | P1: SpendThreshold | Q1: SpendOpt | R1: VolumeOpt | S1: ContribOpt | T1: SaturationOpt
A2: Week_40_old | B2: FiFi | C2: tv.fifi | E2: =IF(RIGHT(A2,3)="old","Initial",B2&"-"&C2) -> Initial | F2: =Data!AN2 -> 393432.47 | G2: =Data!AP2 -> 6.2941961 | H2: =VLOOKUP(C2,parms,3,FALSE) -> 0.030461531 | I2: =VLOOKUP(C2,parms,8,FALSE) -> 3.15 | J2: =VLOOKUP(C2,parms,4,FALSE) -> 63.027153 | K2: =VLOOKUP(C2,parms,6,FALSE) -> 0.65 | L2: =Data!BL2 -> 1830.2632 | M2: =VLOOKUP(C2,Data!$CB$2:$EB$22,1+VALUE(MID(A2,6,2)),FALSE) -> 3043.56 | P2: 3500 | Q2: 3043.56 | R2: 312.06563 | S2: 3143.6771 | T2: 0.026038982
A3: Week_41_old | B3: FiFi | C3: tv.fifi | E3: =IF(RIGHT(A3,3)="old","Initial",B3&"-"&C3) -> Initial | F3: =Data!AN3 -> 228081.02 | G3: =Data!AP3 -> 7.9971815 | H3: =H2 -> 0.030461531 | I3: =I2 -> 3.15 | J3: =J2 -> 63.027153 | K3: =K2 -> 0.65 | L3: =Data!BL3 -> 1725.3904 | M3: =VLOOKUP(C3,Data!$CB$2:$EB$22,1+VALUE(MID(A3,6,2)),FALSE) -> 14599.11 | P3: =P2 -> 3500 | Q3: 14599.11 | R3: 976.11696 | S3: 9990.371 | T3: 0.14049504
A4: Week_42_old | B4: FiFi | C4: tv.fifi | E4: =IF(RIGHT(A4,3)="old","Initial",B4&"-"&C4) -> Initial | F4: =Data!AN4 -> 317634.99 | G4: =Data!AP4 -> 6.7548153 | H4: =H3 -> 0.030461531 | I4: =I3 -> 3.15 | J4: =J3 -> 63.027153 | K4: =K3 -> 0.65 | L4: =Data!BL4 -> 1946.9834 | M4: =VLOOKUP(C4,Data!$CB$2:$EB$22,1+VALUE(MID(A4,6,2)),FALSE) -> 396.47 | P4: =P3 -> 3500 | Q4: 396.47 | R4: 935.10609 | S4: 19500.407 | T4: 0.096645317
A5: Week_43_old | B5: FiFi | C5: tv.fifi | E5: =IF(RIGHT(A5,3)="old","Initial",B5&"-"&C5) -> Initial | F5: =Data!AN5 -> 322486.62 | G5: =Data!AP5 -> 6.9739034 | H5: =H4 -> 0.030461531 | I5: =I4 -> 3.15 | J5: =J4 -> 63.027153 | K5: =K4 -> 0.65 | L5: =Data!BL5 -> 1944.8608 | M5: =VLOOKUP(C5,Data!$CB$2:$EB$22,1+VALUE(MID(A5,6,2)),FALSE) -> 44909.79 | P5: =P4 -> 3500 | Q5: 44909.79 | R5: 3448.7758 | S5: 30852.212 | T5: 0.35107631
A6: Week_44_old | B6: FiFi | C6: tv.fifi | E6: =IF(RIGHT(A6,3)="old","Initial",B6&"-"&C6) -> Initial | F6: =Data!AN6 -> 401386.28 | G6: =Data!AP6 -> 6.2238891 | H6: =H5 -> 0.030461531 | I6: =I5 -> 3.15 | J6: =J5 -> 63.027153 | K6: =K5 -> 0.65 | L6: =Data!BL6 -> 2085.2621 | M6: =VLOOKUP(C6,Data!$CB$2:$EB$22,1+VALUE(MID(A6,6,2)),FALSE) -> 1534.66 | P6: =P5 -> 3500 | Q6: 1534.66 | R6: 3103.1839 | S6: 59304.038 | T6: 0.25380095
A7: Week_45_old | B7: FiFi | C7: tv.fifi | E7: =IF(RIGHT(A7,3)="old","Initial",B7&"-"&C7) -> Initial | F7: =Data!AN7 -> 309588.9 | G7: =Data!AP7 -> 6.9990429 | H7: =H6 -> 0.030461531 | I7: =I6 -> 3.15 | J7: =J6 -> 63.027153 | K7: =K6 -> 0.65 | L7: =Data!BL7 -> 1650.6524 | M7: =VLOOKUP(C7,Data!$CB$2:$EB$22,1+VALUE(MID(A7,6,2)),FALSE) -> 51717.14 | P7: =P6 -> 3500 | Q7: 51717.14 | R7: 4688.1192 | S7: 51641.754 | T7: 0.49712034
A8: Week_46_old | B8: FiFi | C8: tv.fifi | E8: =IF(RIGHT(A8,3)="old","Initial",B8&"-"&C8) -> Initial | F8: =Data!AN8 -> 309968.78 | G8: =Data!AP8 -> 6.976701 | H8: =H7 -> 0.030461531 | I8: =I7 -> 3.15 | J8: =J7 -> 63.027153 | K8: =K7 -> 0.65 | L8: =Data!BL8 -> 1731.9975 | M8: =VLOOKUP(C8,Data!$CB$2:$EB$22,1+VALUE(MID(A8,6,2)),FALSE) -> 1858.89 | P8: =P7 -> 3500 | Q8: 1858.89 | R8: 3504.319 | S8: 75154.156 | T8: 0.37113674
A9: Week_47_old | B9: FiFi | C9: tv.fifi | E9: =IF(RIGHT(A9,3)="old","Initial",B9&"-"&C9) -> Initial | F9: =Data!AN9 -> 454180.53 | G9: =Data!AP9 -> 6.0080329 | H9: =H8 -> 0.030461531 | I9: =I8 -> 3.15 | J9: =J8 -> 63.027153 | K9: =K8 -> 0.65 | L9: =Data!BL9 -> 2385.2246 | M9: =VLOOKUP(C9,Data!$CB$2:$EB$22,1+VALUE(MID(A9,6,2)),FALSE) -> 0 | P9: =P8 -> 3500 | Q9: 0 | R9: 3601.1199 | S9: 68152.287 | T9: 0.26028991
A10: Week_48_old | B10: FiFi | C10: tv.fifi | E10: =IF(RIGHT(A10,3)="old","Initial",B10&"-"&C10) -> Initial | F10: =Data!AN10 -> 455011.74 | G10: =Data!AP10 -> 6.0449284 | H10: =H9 -> 0.030461531 | I10: =I9 -> 3.15 | J10: =J9 -> 63.027153 | K10: =K9 -> 0.65 | L10: =Data!BL10 -> 2385.2246 | M10: =VLOOKUP(C10,Data!$CB$2:$EB$22,1+VALUE(MID(A10,6,2)),FALSE) -> 0 | P10: =P9 -> 3500 | Q10: 0 | R10: 2466.666 | S10: 46969.081 | T10: 0.17796558
A11: Week_49_old | B11: FiFi | C11: tv.fifi | E11: =IF(RIGHT(A11,3)="old","Initial",B11&"-"&C11) -> Initial | F11: =Data!AN11 -> 290055.89 | G11: =Data!AP11 -> 7.3475859 | H11: =H10 -> 0.030461531 | I11: =I10 -> 3.15 | J11: =J10 -> 63.027153 | K11: =K10 -> 0.65 | L11: =Data!BL11 -> 2385.2246 | M11: =VLOOKUP(C11,Data!$CB$2:$EB$22,1+VALUE(MID(A11,6,2)),FALSE) -> 0 | P11: =P10 -> 3500 | Q11: 0 | R11: 1056.7588 | S11: 24458.573 | T11: 0.11960311
A12: Week_50_old | B12: FiFi | C12: tv.fifi | E12: =IF(RIGHT(A12,3)="old","Initial",B12&"-"&C12) -> Initial | F12: =Data!AN12 -> 348451.97 | G12: =Data!AP12 -> 6.6816215 | H12: =H11 -> 0.030461531 | I12: =I11 -> 3.15 | J12: =J11 -> 63.027153 | K12: =K11 -> 0.65 | L12: =Data!BL12 -> 2011.4208 | M12: =VLOOKUP(C12,Data!$CB$2:$EB$22,1+VALUE(MID(A12,6,2)),FALSE) -> 0 | P12: =P11 -> 3500 | Q12: 0 | R12: 843.45555 | S12: 17752.3 | T12: 0.079463472
A13: Week_51_old | B13: FiFi | C13: tv.fifi | E13: =IF(RIGHT(A13,3)="old","Initial",B13&"-"&C13) -> Initial | F13: =Data!AN13 -> 427408.08 | G13: =Data!AP13 -> 6.1680815 | H13: =H12 -> 0.030461531 | I13: =I12 -> 3.15 | J13: =J12 -> 63.027153 | K13: =K12 -> 0.65 | L13: =Data!BL13 -> 2011.4208 | M13: =VLOOKUP(C13,Data!$CB$2:$EB$22,1+VALUE(MID(A13,6,2)),FALSE) -> 0 | P13: =P12 -> 3500 | Q13: 0 | R13: 682.17617 | S13: 13254.312 | T13: 0.052396476
A14: Week_52_old | B14: FiFi | C14: tv.fifi | E14: =IF(RIGHT(A14,3)="old","Initial",B14&"-"&C14) -> Initial | F14: =Data!AN14 -> 330189.5 | G14: =Data!AP14 -> 6.4579352 | H14: =H13 -> 0.030461531 | I14: =I13 -> 3.15 | J14: =J13 -> 63.027153 | K14: =K13 -> 0.65 | L14: =Data!BL14 -> 2011.4208 | M14: =VLOOKUP(C14,Data!$CB$2:$EB$22,1+VALUE(MID(A14,6,2)),FALSE) -> 0 | P14: =P13 -> 3500 | Q14: 0 | R14: 345.77253 | S14: 7033.8764 | T14: 0.034377596
A15: Week_01 | B15: FiFi | C15: tv.fifi | E15: =IF(RIGHT(A15,3)="old","Initial",B15&"-"&C15) -> FiFi-tv.fifi | F15: =Data!AN15 -> 340832.86 | G15: =Data!AP15 -> 6.8003507 | H15: =H14 -> 0.030461531 | I15: =I14 -> 3.15 | J15: =J14 -> 63.027153 | K15: =K14 -> 0.65 | L15: =Data!BL15 -> 2011.4208 | P15: =P14 -> 3500 | Q15: 71471.962 | R15: 4606.9982 | S15: 27215.029 | T15: 0.44373619
A16: Week_02 | B16: FiFi | C16: tv.fifi | E16: =IF(RIGHT(A16,3)="old","Initial",B16&"-"&C16) -> FiFi-tv.fifi | F16: =Data!AN16 -> 439217.37 | G16: =Data!AP16 -> 6.2729203 | H16: =H15 -> 0.030461531 | I16: =I15 -> 3.15 | J16: =J15 -> 63.027153 | K16: =K15 -> 0.65 | L16: =Data!BL16 -> 1316.369 | P16: =P15 -> 3500 | Q16: 69864.76 | R16: 9442.3419 | S16: 116713.07 | T16: 0.70574609
A17: Week_03 | B17: FiFi | C17: tv.fifi | E17: =IF(RIGHT(A17,3)="old","Initial",B17&"-"&C17) -> FiFi-tv.fifi | F17: =Data!AN17 -> 392882.01 | G17: =Data!AP17 -> 6.5115708 | H17: =H16 -> 0.030461531 | I17: =I16 -> 3.15 | J17: =J16 -> 63.027153 | K17: =K16 -> 0.65 | L17: =Data!BL17 -> 1613.3688 | P17: =P16 -> 3500 | Q17: 11944.44 | R17: 7163.053 | S17: 134980.15 | T17: 0.59852775
A18: Week_04 | B18: FiFi | C18: tv.fifi | E18: =IF(RIGHT(A18,3)="old","Initial",B18&"-"&C18) -> FiFi-tv.fifi | F18: =Data!AN18 -> 287120.72 | G18: =Data!AP18 -> 7.4241409 | H18: =H17 -> 0.030461531 | I18: =I17 -> 3.15 | J18: =J17 -> 63.027153 | K18: =K17 -> 0.65 | L18: =Data!BL18 -> 1235.0682 | P18: =P17 -> 3500 | Q18: 31953.064 | R18: 5540.4404 | S18: 97615.919 | T18: 0.63347287
A19: Week_05 | B19: FiFi | C19: tv.fifi | E19: =IF(RIGHT(A19,3)="old","Initial",B19&"-"&C19) -> FiFi-tv.fifi | F19: =Data!AN19 -> 319043.21 | G19: =Data!AP19 -> 7.2881301 | H19: =H18 -> 0.030461531 | I19: =I18 -> 3.15 | J19: =J18 -> 63.027153 | K19: =K18 -> 0.65 | L19: =Data!BL19 -> 1600.0804 | P19: =P18 -> 3500 | Q19: 18929.073 | R19: 5523.3322 | S19: 107873.43 | T19: 0.56832913
A20: Week_06 | B20: FiFi | C20: tv.fifi | E20: =IF(RIGHT(A20,3)="old","Initial",B20&"-"&C20) -> FiFi-tv.fifi | F20: =Data!AN20 -> 242439.85 | G20: =Data!AP20 -> 8.3972136 | H20: =H19 -> 0.030461531 | I20: =I19 -> 3.15 | J20: =J19 -> 63.027153 | K20: =K19 -> 0.65 | L20: =Data!BL20 -> 1560.3789 | P20: =P19 -> 3500 | Q20: 19946.281 | R20: 3892.699 | S20: 83020.369 | T20: 0.52710251
A21: Week_07 | B21: FiFi | C21: tv.fifi | E21: =IF(RIGHT(A21,3)="old","Initial",B21&"-"&C21) -> FiFi-tv.fifi | F21: =Data!AN21 -> 452969.13 | G21: =Data!AP21 -> 6.5182322 | H21: =H20 -> 0.030461531 | I21: =I20 -> 3.15 | J21: =J20 -> 63.027153 | K21: =K20 -> 0.65 | L21: =Data!BL21 -> 1755.0705 | P21: =P20 -> 3500 | Q21: 50408.301 | R21: 8421.4986 | S21: 122505.54 | T21: 0.61033607
A22: Week_08 | B22: FiFi | C22: tv.fifi | E22: =IF(RIGHT(A22,3)="old","Initial",B22&"-"&C22) -> FiFi-tv.fifi | F22: =Data!AN22 -> 374829.34 | G22: =Data!AP22 -> 7.0414807 | H22: =H21 -> 0.030461531 | I22: =I21 -> 3.15 | J22: =J21 -> 63.027153 | K22: =K21 -> 0.65 | L22: =Data!BL22 -> 1419.9591 | P22: =P21 -> 3500 | Q22: 41982.615 | R22: 7547.0273 | S22: 125415.46 | T22: 0.66098349
A23: Week_09 | B23: FiFi | C23: tv.fifi | E23: =IF(RIGHT(A23,3)="old","Initial",B23&"-"&C23) -> FiFi-tv.fifi | F23: =Data!AN23 -> 369195.69 | G23: =Data!AP23 -> 6.974184 | H23: =H22 -> 0.030461531 | I23: =I22 -> 3.15 | J23: =J22 -> 63.027153 | K23: =K22 -> 0.65 | L23: =Data!BL23 -> 1825.6779 | P23: =P22 -> 3500 | Q23: 11280.911 | R23: 6198.7845 | S23: 124898.2 | T23: 0.551186
A24: Week_10 | B24: FiFi | C24: tv.fifi | E24: =IF(RIGHT(A24,3)="old","Initial",B24&"-"&C24) -> FiFi-tv.fifi | F24: =Data!AN24 -> 327686.09 | G24: =Data!AP24 -> 7.4058431 | H24: =H23 -> 0.030461531 | I24: =I23 -> 3.15 | J24: =J23 -> 63.027153 | K24: =K23 -> 0.65 | L24: =Data!BL24 -> 1504.6108 | P24: =P23 -> 3500 | Q24: 41399.672 | R24: 6149.5438 | S24: 102059.38 | T24: 0.61607439
A25: Week_11 | B25: FiFi | C25: tv.fifi | E25: =IF(RIGHT(A25,3)="old","Initial",B25&"-"&C25) -> FiFi-tv.fifi | F25: =Data!AN25 -> 447161.26 | G25: =Data!AP25 -> 6.5316917 | H25: =H24 -> 0.030461531 | I25: =I24 -> 3.15 | J25: =J24 -> 63.027153 | K25: =K24 -> 0.65 | L25: =Data!BL25 -> 1970.6821 | P25: =P24 -> 3500 | Q25: 25899.868 | R25: 7686.2777 | S25: 132243.98 | T25: 0.56428716
A26: Week_12 | B26: FiFi | C26: tv.fifi | E26: =IF(RIGHT(A26,3)="old","Initial",B26&"-"&C26) -> FiFi-tv.fifi | F26: =Data!AN26 -> 382858.71 | G26: =Data!AP26 -> 6.8320566 | H26: =H25 -> 0.030461531 | I26: =I25 -> 3.15 | J26: =J25 -> 63.027153 | K26: =K25 -> 0.65 | L26: =Data!BL26 -> 1732.3697 | P26: =P25 -> 3500 | Q26: 34287.041 | R26: 6697.7747 | S26: 109855.62 | T26: 0.57430192
... A66: Week_52 | B66: FiFi | C66: tv.fifi | E66: =IF(RIGHT(A66,3)="old","Initial",B66&"-"&C66) -> FiFi-tv.fifi | F66: =Data!AN66 -> 330189.5 | G66: =Data!AP66 -> 6.4579352 | H66: =H65 -> 0.030461531 | I66: =I65 -> 3.15 | J66: =J65 -> 63.027153 | K66: =K65 -> 0.65 | L66: =Data!BL66 -> 2011.4208 | P66: =P65 -> 3500 | Q66: 0 | R66: 3695.3371 | S66: 75172.381 | T66: 0.36739993
A68: Week_40_old | B68: FiFi | C68: tv.fifi | D68: =A68&"-generic-cofi" -> Week_40_old-generic-cofi | E68: =IF(RIGHT(A68,3)="old","Initial",B68&"-"&C68) -> Initial | H68: =SUMIFS(Data!N$2:N$48,Data!$L$2:$L$48,$C68,Data!$M$2:$M$48,RIGHT($D68,4)) -> 0.0041802592 | I68: =VLOOKUP(C68,parms,8,FALSE) -> 3.15 | J68: =SUMIFS(Data!O$2:O$48,Data!$L$2:$L$48,$C68,Data!$M$2:$M$48,RIGHT($D68,4)) -> 84.453237 | K68: =SUMIFS(Data!Q$2:Q$48,Data!$L$2:$L$48,$C68,Data!$M$2:$M$48,RIGHT($D68,4)) -> 0.65 | L68: =Data!BL2 -> 1830.2632 | Q68: 0 | R68: 8.2454943 | S68: 184.49269 | T68: 0.019497698
A69: Week_41_old | B69: FiFi | C69: tv.fifi | D69: =A69&"-generic-cofi" -> Week_41_old-generic-cofi | E69: =IF(RIGHT(A69,3)="old","Initial",B69&"-"&C69) -> Initial | H69: =H68 -> 0.0041802592 | I69: =I68 -> 3.15 | J69: =J68 -> 84.453237 | K69: =K68 -> 0.65 | L69: =Data!BL3 -> 1725.3904 | Q69: 0 | R69: 65.774375 | S69: 1286.9031 | T69: 0.10683889
A70: Week_42_old | B70: FiFi | C70: tv.fifi | D70: =A70&"-generic-cofi" -> Week_42_old-generic-cofi | E70: =IF(RIGHT(A70,3)="old","Initial",B70&"-"&C70) -> Initial | H70: =H69 -> 0.0041802592 | I70: =I69 -> 3.15 | J70: =J69 -> 84.453237 | K70: =K69 -> 0.65 | L70: =Data!BL4 -> 1946.9834 | Q70: 0 | R70: 42.75948 | S70: 860.39271 | T70: 0.073048086
A71: Week_43_old | B71: FiFi | C71: tv.fifi | D71: =A71&"-generic-cofi" -> Week_43_old-generic-cofi | E71: =IF(RIGHT(A71,3)="old","Initial",B71&"-"&C71) -> Initial | H71: =H70 -> 0.0041802592 | I71: =I70 -> 3.15 | J71: =J70 -> 84.453237 | K71: =K70 -> 0.65 | L71: =Data!BL5 -> 1944.8608 | Q71: 0 | R71: 120.30841 | S71: 2693.1984 | T71: 0.2758296
A72: Week_44_old | B72: FiFi | C72: tv.fifi | D72: =A72&"-generic-cofi" -> Week_44_old-generic-cofi | E72: =IF(RIGHT(A72,3)="old","Initial",B72&"-"&C72) -> Initial | H72: =H71 -> 0.0041802592 | I72: =I71 -> 3.15 | J72: =J71 -> 84.453237 | K72: =K71 -> 0.65 | L72: =Data!BL6 -> 2085.2621 | Q72: 0 | R72: 85.467946 | S72: 1951.6767 | T72: 0.19626681
A73: Week_45_old | B73: FiFi | C73: tv.fifi | D73: =A73&"-generic-cofi" -> Week_45_old-generic-cofi | E73: =IF(RIGHT(A73,3)="old","Initial",B73&"-"&C73) -> Initial | H73: =H72 -> 0.0041802592 | I73: =I72 -> 3.15 | J73: =J72 -> 84.453237 | K73: =K72 -> 0.65 | L73: =Data!BL7 -> 1650.6524 | Q73: 0 | R73: 280.27004 | S73: 5394.339 | T73: 0.40130768
A74: Week_46_old | B74: FiFi | C74: tv.fifi | D74: =A74&"-generic-cofi" -> Week_46_old-generic-cofi | E74: =IF(RIGHT(A74,3)="old","Initial",B74&"-"&C74) -> Initial | H74: =H73 -> 0.0041802592 | I74: =I73 -> 3.15 | J74: =J73 -> 84.453237 | K74: =K73 -> 0.65 | L74: =Data!BL8 -> 1731.9975 | Q74: 0 | R74: 164.71447 | S74: 3466.94 | T74: 0.29260299
A75: Week_47_old | B75: FiFi | C75: tv.fifi | D75: =A75&"-generic-cofi" -> Week_47_old-generic-cofi | E75: =IF(RIGHT(A75,3)="old","Initial",B75&"-"&C75) -> Initial | H75: =H74 -> 0.0041802592 | I75: =I74 -> 3.15 | J75: =J74 -> 84.453237 | K75: =K74 -> 0.65 | L75: =Data!BL9 -> 2385.2246 | Q75: 0 | R75: 103.35035 | S75: 2204.5517 | T75: 0.20148865
A76: Week_48_old | B76: FiFi | C76: tv.fifi | D76: =A76&"-generic-cofi" -> Week_48_old-generic-cofi | E76: =IF(RIGHT(A76,3)="old","Initial",B76&"-"&C76) -> Initial | H76: =H75 -> 0.0041802592 | I76: =I75 -> 3.15 | J76: =J75 -> 84.453237 | K76: =K75 -> 0.65 | L76: =Data!BL10 -> 2385.2246 | Q76: 0 | R76: 59.139061 | S76: 1333.4791 | T76: 0.13606173
A77: Week_49_old | B77: FiFi | C77: tv.fifi | D77: =A77&"-generic-cofi" -> Week_49_old-generic-cofi | E77: =IF(RIGHT(A77,3)="old","Initial",B77&"-"&C77) -> Initial | H77: =H76 -> 0.0041802592 | I77: =I76 -> 3.15 | J77: =J76 -> 84.453237 | K77: =K76 -> 0.65 | L77: =Data!BL11 -> 2385.2246 | Q77: 0 | R77: 42.377995 | S77: 932.22778 | T77: 0.090686243
A78: Week_50_old | B78: FiFi | C78: tv.fifi | D78: =A78&"-generic-cofi" -> Week_50_old-generic-cofi | E78: =IF(RIGHT(A78,3)="old","Initial",B78&"-"&C78) -> Initial | H78: =H77 -> 0.0041802592 | I78: =I77 -> 3.15 | J78: =J77 -> 84.453237 | K78: =K77 -> 0.65 | L78: =Data!BL12 -> 2011.4208 | Q78: 0 | R78: 42.454711 | S78: 818.99333 | T78: 0.059921879
A79: Week_51_old | B79: FiFi | C79: tv.fifi | D79: =A79&"-generic-cofi" -> Week_51_old-generic-cofi | E79: =IF(RIGHT(A79,3)="old","Initial",B79&"-"&C79) -> Initial | H79: =H78 -> 0.0041802592 | I79: =I78 -> 3.15 | J79: =J78 -> 84.453237 | K79: =K78 -> 0.65 | L79: =Data!BL13 -> 2011.4208 | Q79: 0 | R79: 17.113116 | S79: 386.42048 | T79: 0.039369073
A80: Week_52_old | B80: FiFi | C80: tv.fifi | D80: =A80&"-generic-cofi" -> Week_52_old-generic-cofi | E80: =IF(RIGHT(A80,3)="old","Initial",B80&"-"&C80) -> Initial | H80: =H79 -> 0.0041802592 | I80: =I79 -> 3.15 | J80: =J79 -> 84.453237 | K80: =K79 -> 0.65 | L80: =Data!BL14 -> 2011.4208 | Q80: 0 | R80: 11.048636 | S80: 228.58035 | T80: 0.025769399
...

Sheet Opt_current
A1: Period | B1: Product | C1: Media | D1: Halo | E1: Group | F1: VolumeBase | G1: Price | H1: UpliftMax | I1: UpliftFactor | J1: UnitSlope | K1: Carryover | L1: CostPerUnit | M1: SpendFixed | N1: SpendMin | O1: SpendMax | P1: SpendThreshold | Q1: SpendOpt | R1: VolumeOpt | S1: ContribOpt | T1: SaturationOpt
A2: Week_40_old | B2: FiFi | C2: tv.fifi | E2: =IF(RIGHT(A2,3)="old","Initial",B2&"-"&C2) -> Initial | F2: =Data!AN2 -> 393432.47 | G2: =Data!AP2 -> 6.2941961 | H2: =VLOOKUP(C2,parms,3,FALSE) -> 0.030461531 | I2: =VLOOKUP(C2,parms,8,FALSE) -> 3.15 | J2: =VLOOKUP(C2,parms,4,FALSE) -> 63.027153 | K2: =VLOOKUP(C2,parms,6,FALSE) -> 0.65 | L2: =Data!BL2 -> 1830.2632 | M2: =VLOOKUP(C2,Data!$CB$2:$EB$22,1+VALUE(MID(A2,6,2)),FALSE) -> 3043.56 | Q2: 3043.56 | R2: 312.06563 | S2: 3143.6771 | T2: 0.026038982
A3: Week_41_old | B3: FiFi | C3: tv.fifi | E3: =IF(RIGHT(A3,3)="old","Initial",B3&"-"&C3) -> Initial | F3: =Data!AN3 -> 228081.02 | G3: =Data!AP3 -> 7.9971815 | H3: =H2 -> 0.030461531 | I3: =I2 -> 3.15 | J3: =J2 -> 63.027153 | K3: =K2 -> 0.65 | L3: =Data!BL3 -> 1725.3904 | M3: =VLOOKUP(C3,Data!$CB$2:$EB$22,1+VALUE(MID(A3,6,2)),FALSE) -> 14599.11 | Q3: 14599.11 | R3: 976.11696 | S3: 9990.371 | T3: 0.14049504
A4: Week_42_old | B4: FiFi | C4: tv.fifi | E4: =IF(RIGHT(A4,3)="old","Initial",B4&"-"&C4) -> Initial | F4: =Data!AN4 -> 317634.99 | G4: =Data!AP4 -> 6.7548153 | H4: =H3 -> 0.030461531 | I4: =I3 -> 3.15 | J4: =J3 -> 63.027153 | K4: =K3 -> 0.65 | L4: =Data!BL4 -> 1946.9834 | M4: =VLOOKUP(C4,Data!$CB$2:$EB$22,1+VALUE(MID(A4,6,2)),FALSE) -> 396.47 | Q4: 396.47 | R4: 935.10609 | S4: 19500.407 | T4: 0.096645317
A5: Week_43_old | B5: FiFi | C5: tv.fifi | E5: =IF(RIGHT(A5,3)="old","Initial",B5&"-"&C5) -> Initial | F5: =Data!AN5 -> 322486.62 | G5: =Data!AP5 -> 6.9739034 | H5: =H4 -> 0.030461531 | I5: =I4 -> 3.15 | J5: =J4 -> 63.027153 | K5: =K4 -> 0.65 | L5: =Data!BL5 -> 1944.8608 | M5: =VLOOKUP(C5,Data!$CB$2:$EB$22,1+VALUE(MID(A5,6,2)),FALSE) -> 44909.79 | Q5: 44909.79 | R5: 3448.7758 | S5: 30852.212 | T5: 0.35107631
A6: Week_44_old | B6: FiFi | C6: tv.fifi | E6: =IF(RIGHT(A6,3)="old","Initial",B6&"-"&C6) -> Initial | F6: =Data!AN6 -> 401386.28 | G6: =Data!AP6 -> 6.2238891 | H6: =H5 -> 0.030461531 | I6: =I5 -> 3.15 | J6: =J5 -> 63.027153 | K6: =K5 -> 0.65 | L6: =Data!BL6 -> 2085.2621 | M6: =VLOOKUP(C6,Data!$CB$2:$EB$22,1+VALUE(MID(A6,6,2)),FALSE) -> 1534.66 | Q6: 1534.66 | R6: 3103.1839 | S6: 59304.038 | T6: 0.25380095
A7: Week_45_old | B7: FiFi | C7: tv.fifi | E7: =IF(RIGHT(A7,3)="old","Initial",B7&"-"&C7) -> Initial | F7: =Data!AN7 -> 309588.9 | G7: =Data!AP7 -> 6.9990429 | H7: =H6 -> 0.030461531 | I7: =I6 -> 3.15 | J7: =J6 -> 63.027153 | K7: =K6 -> 0.65 | L7: =Data!BL7 -> 1650.6524 | M7: =VLOOKUP(C7,Data!$CB$2:$EB$22,1+VALUE(MID(A7,6,2)),FALSE) -> 51717.14 | Q7: 51717.14 | R7: 4688.1192 | S7: 51641.754 | T7: 0.49712034
A8: Week_46_old | B8: FiFi | C8: tv.fifi | E8: =IF(RIGHT(A8,3)="old","Initial",B8&"-"&C8) -> Initial | F8: =Data!AN8 -> 309968.78 | G8: =Data!AP8 -> 6.976701 | H8: =H7 -> 0.030461531 | I8: =I7 -> 3.15 | J8: =J7 -> 63.027153 | K8: =K7 -> 0.65 | L8: =Data!BL8 -> 1731.9975 | M8: =VLOOKUP(C8,Data!$CB$2:$EB$22,1+VALUE(MID(A8,6,2)),FALSE) -> 1858.89 | Q8: 1858.89 | R8: 3504.319 | S8: 75154.156 | T8: 0.37113674
A9: Week_47_old | B9: FiFi | C9: tv.fifi | E9: =IF(RIGHT(A9,3)="old","Initial",B9&"-"&C9) -> Initial | F9: =Data!AN9 -> 454180.53 | G9: =Data!AP9 -> 6.0080329 | H9: =H8 -> 0.030461531 | I9: =I8 -> 3.15 | J9: =J8 -> 63.027153 | K9: =K8 -> 0.65 | L9: =Data!BL9 -> 2385.2246 | M9: =VLOOKUP(C9,Data!$CB$2:$EB$22,1+VALUE(MID(A9,6,2)),FALSE) -> 0 | Q9: 0 | R9: 3601.1199 | S9: 68152.287 | T9: 0.26028991
A10: Week_48_old | B10: FiFi | C10: tv.fifi | E10: =IF(RIGHT(A10,3)="old","Initial",B10&"-"&C10) -> Initial | F10: =Data!AN10 -> 455011.74 | G10: =Data!AP10 -> 6.0449284 | H10: =H9 -> 0.030461531 | I10: =I9 -> 3.15 | J10: =J9 -> 63.027153 | K10: =K9 -> 0.65 | L10: =Data!BL10 -> 2385.2246 | M10: =VLOOKUP(C10,Data!$CB$2:$EB$22,1+VALUE(MID(A10,6,2)),FALSE) -> 0 | Q10: 0 | R10: 2466.666 | S10: 46969.081 | T10: 0.17796558
A11: Week_49_old | B11: FiFi | C11: tv.fifi | E11: =IF(RIGHT(A11,3)="old","Initial",B11&"-"&C11) -> Initial | F11: =Data!AN11 -> 290055.89 | G11: =Data!AP11 -> 7.3475859 | H11: =H10 -> 0.030461531 | I11: =I10 -> 3.15 | J11: =J10 -> 63.027153 | K11: =K10 -> 0.65 | L11: =Data!BL11 -> 2385.2246 | M11: =VLOOKUP(C11,Data!$CB$2:$EB$22,1+VALUE(MID(A11,6,2)),FALSE) -> 0 | Q11: 0 | R11: 1056.7588 | S11: 24458.573 | T11: 0.11960311
A12: Week_50_old | B12: FiFi | C12: tv.fifi | E12: =IF(RIGHT(A12,3)="old","Initial",B12&"-"&C12) -> Initial | F12: =Data!AN12 -> 348451.97 | G12: =Data!AP12 -> 6.6816215 | H12: =H11 -> 0.030461531 | I12: =I11 -> 3.15 | J12: =J11 -> 63.027153 | K12: =K11 -> 0.65 | L12: =Data!BL12 -> 2011.4208 | M12: =VLOOKUP(C12,Data!$CB$2:$EB$22,1+VALUE(MID(A12,6,2)),FALSE) -> 0 | Q12: 0 | R12: 843.45555 | S12: 17752.3 | T12: 0.079463472
A13: Week_51_old | B13: FiFi | C13: tv.fifi | E13: =IF(RIGHT(A13,3)="old","Initial",B13&"-"&C13) -> Initial | F13: =Data!AN13 -> 427408.08 | G13: =Data!AP13 -> 6.1680815 | H13: =H12 -> 0.030461531 | I13: =I12 -> 3.15 | J13: =J12 -> 63.027153 | K13: =K12 -> 0.65 | L13: =Data!BL13 -> 2011.4208 | M13: =VLOOKUP(C13,Data!$CB$2:$EB$22,1+VALUE(MID(A13,6,2)),FALSE) -> 0 | Q13: 0 | R13: 682.17617 | S13: 13254.312 | T13: 0.052396476
A14: Week_52_old | B14: FiFi | C14: tv.fifi | E14: =IF(RIGHT(A14,3)="old","Initial",B14&"-"&C14) -> Initial | F14: =Data!AN14 -> 330189.5 | G14: =Data!AP14 -> 6.4579352 | H14: =H13 -> 0.030461531 | I14: =I13 -> 3.15 | J14: =J13 -> 63.027153 | K14: =K13 -> 0.65 | L14: =Data!BL14 -> 2011.4208 | M14: =VLOOKUP(C14,Data!$CB$2:$EB$22,1+VALUE(MID(A14,6,2)),FALSE) -> 0 | Q14: 0 | R14: 345.77253 | S14: 7033.8764 | T14: 0.034377596
... A66: Week_52 | B66: FiFi | C66: tv.fifi | E66: =IF(RIGHT(A66,3)="old","Initial",B66&"-"&C66) -> FiFi-tv.fifi | F66: =Data!AN66 -> 330189.5 | G66: =Data!AP66 -> 6.4579352 | H66: =H65 -> 0.030461531 | I66: =I65 -> 3.15 | J66: =J65 -> 63.027153 | K66: =K65 -> 0.65 | L66: =Data!BL66 -> 2011.4208 | M66: =VLOOKUP(C66,Data!$CB$2:$EB$22,1+VALUE(MID(A66,6,2)),FALSE) -> 0 | Q66: 0 | R66: 374.20653 | S66: 7612.2949 | T66: 0.037204577
A68: Week_40_old | B68: FiFi | C68: tv.fifi | D68: =A68&"-generic-cofi" -> Week_40_old-generic-cofi | E68: =IF(RIGHT(A68,3)="old","Initial",B68&"-"&C68) -> Initial | H68: =SUMIFS(Data!N$2:N$48,Data!$L$2:$L$48,$C68,Data!$M$2:$M$48,RIGHT($D68,4)) -> 0.0041802592 | I68: =VLOOKUP(C68,parms,8,FALSE) -> 3.15 | J68: =SUMIFS(Data!O$2:O$48,Data!$L$2:$L$48,$C68,Data!$M$2:$M$48,RIGHT($D68,4)) -> 84.453237 | K68: =SUMIFS(Data!Q$2:Q$48,Data!$L$2:$L$48,$C68,Data!$M$2:$M$48,RIGHT($D68,4)) -> 0.65 | L68: =Data!BL2 -> 1830.2632 | Q68: 0 | R68: 8.2454943 | S68: 184.49269 | T68: 0.019497698
